Workbook

Sheet Tabla dinam gestion comercial
A1: Territorio | B1: Empleado | C1: Meta Cobertura y Visitas | D1: Clientes Visitados | E1: Cobertura Clientes | F1: Cant. Visitas | G1: Ejec. Visitas | H1: Meta Clientes Recuperar | I1: Cant. Clientes Nuevos | J1: Ejec. Clientes Nuevos | K1: Mes | L1: METAVISITAS | M1: Comercial | N1: Territorio | O1: Cargo | P1: Empresa | Q1: Meta Parcelas | R1: Meta Actividades | S1: META | T1: Meta hectareas | U1: cultivos
A2: GALAGRO BAJO CAUCA ANT. | B2: Yeison Antonio Arenilla Diaz | C2: 62 | D2: 25 | E2: 0.40322581 | F2: 26 | G2: 0.41935484 | H2: 38 | I2: 8 | J2: 0.21052632 | K2: Abril | L2: =Tabla18[[#This Row],[Meta Cobertura y Visitas]] -> 62 | M2: Yuri Andrea Garro Sánchez | N2: GALAGRO ANTIOQUIA DIRECCIÓN | O2: DIR GALAGRO ANTIOQUIA | P2: GALAGRO | Q2: =SUM(Q3:Q18) -> 8 | R2: =SUM(R3:R18) -> 48 | S2: =R2+Q2 -> 56 | T2: =SUM(T3:T18) -> 480 | U2: =SUM(U3:U18) -> 48 | V2: Excelente | W2: >=90%
A3: GALAGRO CORDOBA ANT. | B3: Karen Paola Hernández Pacheco | C3: 124 | D3: 29 | E3: 0.23387097 | F3: 35 | G3: 0.28225806 | H3: 220 | I3: 9 | J3: 0.040909091 | K3: Abril | L3: =Tabla18[[#This Row],[Meta Cobertura y Visitas]] -> 124 | M3: Yeison Antonio Arenilla Diaz | N3: GALAGRO BAJO CAUCA ANT. | O3: RC GALAGRO BAJO CAUCA | P3: GALAGRO | Q3: 0.5 | R3: 3 | S3: =R3+Q3 -> 3.5 | T3: 30 | U3: 3 | V3: Destacado | W3: 75%<>90%
A4: GALAGRO CORDOBA ANT. | B4: Stefanía Builes Rodríguez | D4: 1 | F4: 1 | K4: Abril | L4: =Tabla18[[#This Row],[Meta Cobertura y Visitas]] -> 0 | M4: (Vacante) Karen Paola Hernandez Pacheco | N4: GALAGRO CORDOBA ANT. | O4: PROMOTOR GALAGRO CORDOBA | P4: GALAGRO | Q4: 0.5 | R4: 3 | S4: =R4+Q4 -> 3.5 | T4: 30 | U4: 3 | V4: En desarrollo | W4: <74%
A5: GALAGRO NORDESTE Y MAG. MEDIO ANT. | B5: (vacante) Maria Alejandra Duque Laverde | C5: 74 | H5: 40 | I5: 7 | J5: 0.175 | K5: Abril | L5: =Tabla18[[#This Row],[Meta Cobertura y Visitas]] -> 74 | M5: Karen Paola Hernández Pacheco | N5: GALAGRO CORDOBA ANT. | O5: RTC GALAGRO CORDOBA | P5: GALAGRO | Q5: 0.5 | R5: 3 | S5: =R5+Q5 -> 3.5 | T5: 30 | U5: 3 | V5: Crítico | W5: <60%
A6: GALAGRO NORTE ANT. | B6: Luisa Fernanda Quiceno Restrepo | C6: 86 | D6: 16 | E6: 0.18604651 | F6: 25 | G6: 0.29069767 | H6: 47 | I6: 5 | J6: 0.10638298 | K6: Abril | L6: =Tabla18[[#This Row],[Meta Cobertura y Visitas]] -> 86 | M6: (vacante) Maria Alejandra Duque Laverde | N6: GALAGRO NORDESTE Y MAG. MEDIO ANT. | O6: PROMOTOR GALAGRO NORDESTE ANT | P6: GALAGRO | Q6: 0.5 | R6: 3 | S6: =R6+Q6 -> 3.5 | T6: 30 | U6: 3
A7: GALAGRO NORTE ANT. | B7: Norbey Fernando Montoya Grajales | D7: 1 | F7: 2 | K7: Abril | L7: =Tabla18[[#This Row],[Meta Cobertura y Visitas]] -> 0 | M7: Miguel Andrés León Díaz | N7: GALAGRO NORTE ANT. | O7: PROMOTOR GALAGRO NORTE ANT | P7: GALAGRO | Q7: 0.5 | R7: 3 | S7: =R7+Q7 -> 3.5 | T7: 30 | U7: 3
A8: GALAGRO OFICINA ANT. | B8: Katherine Bedoya Rodas | C8: 4 | D8: 1 | E8: 0.25 | F8: 8 | G8: 2 | H8: 3 | K8: Abril | L8: =Tabla18[[#This Row],[Meta Cobertura y Visitas]] -> 4 | M8: Luisa Fernanda Quiceno Restrepo | N8: GALAGRO NORTE ANT. | O8: RC GALAGRO NORTE ANT | P8: GALAGRO | Q8: 0.5 | R8: 3 | S8: =R8+Q8 -> 3.5 | T8: 30 | U8: 3
A9: GALAGRO ORIENTE A ANT. | B9: Geovanny Andres Monsalve Garcia | C9: 59 | D9: 4 | E9: 0.06779661 | F9: 4 | G9: 0.06779661 | H9: 40 | I9: 3 | J9: 0.075 | K9: Abril | L9: =Tabla18[[#This Row],[Meta Cobertura y Visitas]] -> 59 | M9: Alexander Marulanda Vera | N9: GALAGRO ORIENTE A ANT. | O9: PROMOTOR GALAGRO ORIENTE A ANT | P9: GALAGRO | Q9: 0.5 | R9: 3 | S9: =R9+Q9 -> 3.5 | T9: 30 | U9: 3
A10: GALAGRO ORIENTE B ANT. | B10: Katherine Bedoya Rodas | D10: 1 | F10: 3 | K10: Abril | L10: =Tabla18[[#This Row],[Meta Cobertura y Visitas]] -> 0 | M10: Geovanny Andres Monsalve Garcia | N10: GALAGRO ORIENTE A ANT. | O10: RC GALAGRO ORIENTE A ANT | P10: GALAGRO | Q10: 0.5 | R10: 3 | S10: =R10+Q10 -> 3.5 | T10: 30 | U10: 3
A11: GALAGRO ORIENTE B ANT. | B11: Norbey Fernando Montoya Grajales | C11: 28 | D11: 15 | E11: 0.53571429 | F11: 55 | G11: 1.9642857 | H11: 10 | K11: Abril | L11: =Tabla18[[#This Row],[Meta Cobertura y Visitas]] -> 28 | M11: Brarlyn Steven Garcia Castro | N11: GALAGRO ORIENTE B ANT. | O11: PROMOTOR GALAGRO ORIENTE B ANT | P11: GALAGRO | Q11: 0.5 | R11: 3 | S11: =R11+Q11 -> 3.5 | T11: 30 | U11: 3
A12: GALAGRO SUROESTE ANT. | B12: Katherine Bedoya Rodas | D12: 1 | F12: 3 | K12: Abril | L12: =Tabla18[[#This Row],[Meta Cobertura y Visitas]] -> 0 | M12: Norbey Fernando Montoya Grajales | N12: GALAGRO ORIENTE B ANT. | O12: RC GALAGRO ORIENTE B ANT | P12: GALAGRO | Q12: 0.5 | R12: 3 | S12: =R12+Q12 -> 3.5 | T12: 30 | U12: 3
A13: GALAGRO SUROESTE ANT. | B13: Mónica Lucero Valencia Montoya | C13: 112 | D13: 27 | E13: 0.24107143 | F13: 31 | G13: 0.27678571 | H13: 178 | I13: 10 | J13: 0.056179775 | K13: Abril | L13: =Tabla18[[#This Row],[Meta Cobertura y Visitas]] -> 112 | M13: John Álvaro Correa Castaño | N13: GALAGRO SUROESTE ANT. | O13: PROMOTOR GALAGRO SUROESTE ANT | P13: GALAGRO | Q13: 0.5 | R13: 3 | S13: =R13+Q13 -> 3.5 | T13: 30 | U13: 3
A14: GALAGRO URABA ANT. | B14: Stefanía Builes Rodríguez | C14: 89 | D14: 58 | E14: 0.65168539 | F14: 88 | G14: 0.98876404 | H14: 95 | I14: 2 | J14: 0.021052632 | K14: Abril | L14: =Tabla18[[#This Row],[Meta Cobertura y Visitas]] -> 89 | M14: Mónica Lucero Valencia Montoya | N14: GALAGRO SUROESTE ANT. | O14: RC GALAGRO SUROESTE ANT | P14: GALAGRO | Q14: 0.5 | R14: 3 | S14: =R14+Q14 -> 3.5 | T14: 30 | U14: 3
A15: GALAGRO URABA ANT. | B15: Yeison Antonio Arenilla Diaz | D15: 1 | F15: 1 | K15: Abril | L15: =Tabla18[[#This Row],[Meta Cobertura y Visitas]] -> 0 | M15: (Vacante) José Eliécer Borja David | N15: GALAGRO URABA ANT. | O15: PROMOTOR GALAGRO URABA | P15: GALAGRO | Q15: 0.5 | R15: 3 | S15: =R15+Q15 -> 3.5 | T15: 30 | U15: 3
A16: GALAGRO VALLE DE ABURRA ANT. | B16: Katherine Bedoya Rodas | C16: 81 | D16: 10 | E16: 0.12345679 | F16: 18 | G16: 0.22222222 | H16: 70 | I16: 3 | J16: 0.042857143 | K16: Abril | L16: =Tabla18[[#This Row],[Meta Cobertura y Visitas]] -> 81 | M16: Stefanía Builes Rodríguez | N16: GALAGRO URABA ANT. | O16: RTC GALAGRO URABA | P16: GALAGRO | Q16: 0.5 | R16: 3 | S16: =R16+Q16 -> 3.5 | T16: 30 | U16: 3
A17: GALAGRO VALLE DE ABURRA ANT. | B17: Stefanía Builes Rodríguez | D17: 1 | F17: 1 | K17: Abril | L17: =Tabla18[[#This Row],[Meta Cobertura y Visitas]] -> 0 | M17: Estefania Osorio Usuga | N17: GALAGRO VALLE DE ABURRA ANT. | O17: PROMOTOR GALAGRO VALLE DE ABURRA | P17: GALAGRO | Q17: 0.5 | R17: 3 | S17: =R17+Q17 -> 3.5 | T17: 30 | U17: 3
A18: GALAGRO BAJO CAUCA ANT. | B18: Yeison Antonio Arenilla Diaz | C18: 62 | D18: 15 | E18: 0.24193548 | F18: 16 | G18: 0.25806452 | H18: 38 | I18: 8 | J18: 0.21052632 | K18: Mayo | L18: =Tabla18[[#This Row],[Meta Cobertura y Visitas]] -> 62 | M18: Katherine Bedoya Rodas | N18: GALAGRO VALLE DE ABURRA ANT. | O18: RC GALAGRO VALLE DE ABURRA | P18: GALAGRO | Q18: 0.5 | R18: 3 | S18: =R18+Q18 -> 3.5 | T18: 30 | U18: 3
A19: GALAGRO CORDOBA ANT. | B19: Karen Paola Hernández Pacheco | C19: 124 | D19: 33 | E19: 0.26612903 | F19: 39 | G19: 0.31451613 | H19: 220 | I19: 9 | J19: 0.040909091 | K19: Mayo | L19: =Tabla18[[#This Row],[Meta Cobertura y Visitas]] -> 124
A20: GALAGRO CORDOBA ANT. | B20: Stefanía Builes Rodríguez | D20: 2 | F20: 2 | K20: Mayo | L20: =Tabla18[[#This Row],[Meta Cobertura y Visitas]] -> 0
A21: GALAGRO NORDESTE Y MAG. MEDIO ANT. | B21: (vacante) Maria Alejandra Duque Laverde | C21: 74 | H21: 40 | I21: 7 | J21: 0.175 | K21: Mayo | L21: =Tabla18[[#This Row],[Meta Cobertura y Visitas]] -> 74
A22: GALAGRO NORTE ANT. | B22: Luisa Fernanda Quiceno Restrepo | C22: 86 | D22: 19 | E22: 0.22093023 | F22: 34 | G22: 0.39534884 | H22: 47 | I22: 5 | J22: 0.10638298 | K22: Mayo | L22: =Tabla18[[#This Row],[Meta Cobertura y Visitas]] -> 86
A23: GALAGRO NORTE ANT. | B23: Norbey Fernando Montoya Grajales | D23: 1 | F23: 2 | K23: Mayo | L23: =Tabla18[[#This Row],[Meta Cobertura y Visitas]] -> 0
A24: GALAGRO OFICINA ANT. | B24: Katherine Bedoya Rodas | C24: 4 | D24: 2 | E24: 0.5 | F24: 10 | G24: 2.5 | H24: 3 | K24: Mayo | L24: =Tabla18[[#This Row],[Meta Cobertura y Visitas]] -> 4
A25: GALAGRO ORIENTE A ANT. | B25: Geovanny Andres Monsalve Garcia | C25: 59 | D25: 20 | E25: 0.33898305 | F25: 26 | G25: 0.44067797 | H25: 40 | I25: 3 | J25: 0.075 | K25: Mayo | L25: =Tabla18[[#This Row],[Meta Cobertura y Visitas]] -> 59
A26: GALAGRO ORIENTE A ANT. | B26: Katherine Bedoya Rodas | F26: 1 | K26: Mayo | L26: =Tabla18[[#This Row],[Meta Cobertura y Visitas]] -> 0
A27: GALAGRO ORIENTE B ANT. | B27: Katherine Bedoya Rodas | D27: 1 | F27: 1 | K27: Mayo | L27: =Tabla18[[#This Row],[Meta Cobertura y Visitas]] -> 0
A28: GALAGRO ORIENTE B ANT. | B28: Norbey Fernando Montoya Grajales | C28: 28 | D28: 13 | E28: 0.46428571 | F28: 35 | G28: 1.25 | H28: 10 | K28: Mayo | L28: =Tabla18[[#This Row],[Meta Cobertura y Visitas]] -> 28
A29: GALAGRO SUROESTE ANT. | B29: Katherine Bedoya Rodas | D29: 1 | F29: 1 | K29: Mayo | L29: =Tabla18[[#This Row],[Meta Cobertura y Visitas]] -> 0
A30: GALAGRO SUROESTE ANT. | B30: Mónica Lucero Valencia Montoya | C30: 112 | D30: 20 | E30: 0.17857143 | F30: 27 | G30: 0.24107143 | H30: 178 | I30: 10 | J30: 0.056179775 | K30: Mayo | L30: =Tabla18[[#This Row],[Meta Cobertura y Visitas]] -> 112
A31: GALAGRO URABA ANT. | B31: Karen Paola Hernández Pacheco | D31: 4 | F31: 8 | K31: Mayo | L31: =Tabla18[[#This Row],[Meta Cobertura y Visitas]] -> 0
A32: GALAGRO URABA ANT. | B32: Stefanía Builes Rodríguez | C32: 89 | D32: 69 | E32: 0.7752809 | F32: 84 | G32: 0.94382022 | H32: 95 | I32: 2 | J32: 0.021052632 | K32: Mayo | L32: =Tabla18[[#This Row],[Meta Cobertura y Visitas]] -> 89
A33: GALAGRO VALLE DE ABURRA ANT. | B33: Katherine Bedoya Rodas | C33: 81 | D33: 27 | E33: 0.33333333 | F33: 35 | G33: 0.43209877 | H33: 70 | I33: 3 | J33: 0.042857143 | K33: Mayo | L33: =Tabla18[[#This Row],[Meta Cobertura y Visitas]] -> 81
A34: GALAGRO VALLE DE ABURRA ANT. | B34: Stefanía Builes Rodríguez | D34: 1 | F34: 1 | K34: Mayo | L34: =Tabla18[[#This Row],[Meta Cobertura y Visitas]] -> 0
A35: GALAGRO BAJO CAUCA ANT. | B35: Yeison Antonio Arenilla Diaz | C35: 62 | D35: 31 | E35: 0.5 | F35: 32 | G35: 0.51612903 | H35: 38 | I35: 8 | J35: 0.21052632 | K35: Junio | L35: =Tabla18[[#This Row],[Meta Cobertura y Visitas]] -> 62
A36: GALAGRO CORDOBA ANT. | B36: Karen Paola Hernández Pacheco | C36: 124 | D36: 22 | E36: 0.17741935 | F36: 29 | G36: 0.23387097 | H36: 220 | I36: 9 | J36: 0.040909091 | K36: Junio | L36: =Tabla18[[#This Row],[Meta Cobertura y Visitas]] -> 124
A37: GALAGRO CORDOBA ANT. | B37: Stefanía Builes Rodríguez | D37: 1 | F37: 1 | K37: Junio | L37: =Tabla18[[#This Row],[Meta Cobertura y Visitas]] -> 0
A38: GALAGRO NORDESTE Y MAG. MEDIO ANT. | B38: (vacante) Maria Alejandra Duque Laverde | C38: 74 | H38: 40 | I38: 7 | J38: 0.175 | K38: Junio | L38: =Tabla18[[#This Row],[Meta Cobertura y Visitas]] -> 74
A39: GALAGRO NORTE ANT. | B39: Luisa Fernanda Quiceno Restrepo | C39: 86 | D39: 18 | E39: 0.20930233 | F39: 32 | G39: 0.37209302 | H39: 47 | I39: 5 | J39: 0.10638298 | K39: Junio | L39: =Tabla18[[#This Row],[Meta Cobertura y Visitas]] -> 86
A40: GALAGRO NORTE ANT. | B40: Norbey Fernando Montoya Grajales | D40: 1 | F40: 3 | K40: Junio | L40: =Tabla18[[#This Row],[Meta Cobertura y Visitas]] -> 0
...

Sheet X territorio
A1: #VALUE! | D1: Reporte de desempeño comercial - Territorio
D2: Reporte de desempeño comercial | G2: Nombre | H2: Katherine Bedoya Rodas
D3: Resumen trimestral | G3: Cargo: | H3: =VLOOKUP(H2,'Tabla dinam gestion comercial'!M:O,3,0) -> RC GALAGRO VALLE DE ABURRA
D4: Primer trimestre | G4: Territorio: | H4: =VLOOKUP(H2,'Tabla dinam gestion comercial'!M:N,2,0) -> GALAGRO VALLE DE ABURRA ANT.
D5: Abril - junio de 2026 | G5: Empresa: | H5: =VLOOKUP(H2,'Tabla dinam gestion comercial'!M:P,4,0) -> GALAGRO
A6: Resultado global
A7: =SUMPRODUCT($D$14:$D$25, $F$14:$F$25) -> 0.24090596
K8: Valor | L8: =A7*100 -> 24.090596 | M8: =ROUND(L8,0)&"%" -> 24%
K9: Restante | L9: =100-L8 -> 75.909404
K10: Oculto | L10: 100
A11: =IF(A7>=90%,"Excelente",IF(A7>=75%,"Destacado",IF(A7>=59%,"En desarrollo","Crítico"))) -> Crítico
A12: INDICADORES CLAVE
A13: Indicador | D13: Cumplimiento | E13: Meta | F13: Peso | G13: Gestión real x 3 meses | H13: Meta esperada x 3 meses | I13: Criterios de medición
A14: #VALUE! | B14: Ejecución visitas | C14: =IF(D14>=90%,"⬤",IF(D14>=75%,"⬤",IF(D14>=60%,"⬤","⬤"))) -> ⬤ | D14: =IFERROR(MIN(100%,G14/H14),0) -> 0.30496454 | E14: 0.9 | F14: 0.1 | G14: =SUMIFS('Tabla dinam gestion comercial'!$F:$F,'Tabla dinam gestion comercial'!$A:$A,$H$4) -> 129 | H14: =SUMIFS('Tabla dinam gestion comercial'!$L:$L,'Tabla dinam gestion comercial'!$A:$A,$H$4,'Tabla dinam gestion comercial'!$K:$K,"Abril")+SUMIFS('Tabla dinam gestion comercial'!$L:$L,'Tabla dinam gestion comercial'!$A:$A,$H$4,'Tabla dinam gestion comercial'!$K:$K,"Mayo")+SUMIFS('Tabla dinam gestion comercial'!$L:$L,'Tabla dinam gestion comercial'!$A:$A,$H$4,'Tabla dinam gestion comercial'!$K:$K,"Junio") -> 423 | I14: Compara el total de visitas realizadas por los integrantes del territorio frente a la meta acumulada esperada. Cumplir o superar la meta equivale al 100%, y el resultado refleja el cumplimiento global del territorio en los meses evaluados.
A15: #VALUE! | B15: Cobertura clientes | C15: =IF(D15>=90%,"⬤",IF(D15>=75%,"⬤",IF(D15>=60%,"⬤","⬤"))) -> ⬤ | D15: =IFERROR(MIN(100%,G15/H15),0) -> 0.76470588 | E15: 0.9 | F15: 0.1 | G15: =SUMIFS('Tabla dinam gestion comercial'!$D:$D,'Tabla dinam gestion comercial'!$A:$A,$H$4,'Tabla dinam gestion comercial'!$K:$K,"Abril")+SUMIFS('Tabla dinam gestion comercial'!$D:$D,'Tabla dinam gestion comercial'!$A:$A,$H$4,'Tabla dinam gestion comercial'!$K:$K,"Mayo")+SUMIFS('Tabla dinam gestion comercial'!$D:$D,'Tabla dinam gestion comercial'!$A:$A,$H$4,'Tabla dinam gestion comercial'!$K:$K,"Junio") -> 65 | H15: =(SUMIFS('Tabla dinam gestion comercial'!$C:$C,'Tabla dinam gestion comercial'!$A:$A,$H$4,'Tabla dinam gestion comercial'!$K:$K,"Abril")+SUMIFS('Tabla dinam gestion comercial'!$C:$C,'Tabla dinam gestion comercial'!$A:$A,$H$4,'Tabla dinam gestion comercial'!$K:$K,"Mayo")+SUMIFS('Tabla dinam gestion comercial'!$C:$C,'Tabla dinam gestion comercial'!$A:$A,$H$4,'Tabla dinam gestion comercial'!$K:$K,"Junio"))/3 -> 85 | I15: Mide la cobertura promedio mensual de clientes visitados por el territorio frente a la meta asignada. Se suman los clientes visitados por los integrantes del equipo en cada mes y luego se calcula el promedio del período evaluado. La meta de cobertura es mensual y no se acumula entre meses.
A16: #VALUE! | B16: Nuevos clientes | C16: =IF(D16>=90%,"⬤",IF(D16>=75%,"⬤",IF(D16>=60%,"⬤","⬤"))) -> ⬤ | D16: =IFERROR(G16/H16,0) -> 0.15 | E16: 0.9 | F16: 0.1 | G16: =SUMIFS('Tabla dinam gestion comercial'!$I:$I,'Tabla dinam gestion comercial'!$A:$A,$H$4,'Tabla dinam gestion comercial'!$K:$K,"Junio") -> 3 | H16: =ROUNDUP((SUMIFS('Tabla dinam gestion comercial'!$H:$H,'Tabla dinam gestion comercial'!$A:$A,$H$4,'Tabla dinam gestion comercial'!$K:$K,"Abril")+SUMIFS('Tabla dinam gestion comercial'!$H:$H,'Tabla dinam gestion comercial'!$A:$A,$H$4,'Tabla dinam gestion comercial'!$K:$K,"mayo")+SUMIFS('Tabla dinam gestion comercial'!$H:$H,'Tabla dinam gestion comercial'!$A:$A,$H$4,'Tabla dinam gestion comercial'!$K:$K,"Junio"))/12,0) -> 20 | I16: Mide los clientes nuevos y recuperados del territorio que registran gestión o venta. La meta se calcula de forma proporcional al período evaluado, tomando la meta anual dividida entre 12 meses.
A17: Indicador | D17: Cumplimiento | E17: Meta | F17: Peso | G17: Gestión real | H17: Meta acum. período | I17: Criterios de medición
A18: #VALUE! | B18: Recomendados | C18: =IF(D18>=90%,"⬤",IF(D18>=75%,"⬤",IF(D18>=60%,"⬤","⬤"))) -> ⬤ | D18: =IFERROR((G18/H18),"0") -> 0.2585771 | E18: 0.9 | F18: 0.2 | G18: =SUMIFS(Tecnico!$D:$D,Tecnico!$A:$A,$H$4) -> 233603100 | H18: =SUMIFS(Tecnico!$C:$C,Tecnico!$A:$A,$H$4) -> 903417581 | I18: Suma las recomendaciones generadas en el trimestre, y compara ese total contra la meta acumulada del período. El resultado muestra qué porcentaje de la meta trimestral se alcanzó.
A19: #VALUE! | B19: Referencias | C19: =IF(D19>=90%,"⬤",IF(D19>=75%,"⬤",IF(D19>=60%,"⬤","⬤"))) -> ⬤ | D19: =IF(AND(G19=0, H19=0), 100%, IF(G19=0, 0%, G19/H19)) -> 0.10080645 | E19: 0.9 | F19: 0.1 | G19: =SUMIFS(Tecnico!$J:$J,Tecnico!$A:$A,$H$4) -> 25 | H19: =SUMIFS(Tecnico!$H:$H,Tecnico!$A:$A,$H$4)/3 -> 248 | I19: Mide cuántas referencias se gestionaron frente a la meta esperada. Se suman las referencias del trimestre, y se comparan contra la meta promedio.
A20: Indicador | D20: Cumplimiento | E20: Meta | F20: Peso | G20: Gestión real | H20: Meta acum. período | I20: Criterios de medición
A21: #VALUE! | B21: leads calificados | C21: =IF(D21>=90%,"⬤",IF(D21>=75%,"⬤",IF(D21>=60%,"⬤","⬤"))) -> ⬤ | D21: =IF(H21=0,0,IFERROR(G21/H21,0)) -> 0 | E21: 0.9 | F21: 0.1 | G21: =SUMIFS(Leads!$P:$P,Leads!$L:$L,$H$4) -> 0 | H21: {=IFERROR(COUNTA(_xlfn.UNIQUE(_xlfn._xlws.FILTER('Tabla dinam gestion comercial'!$M:$M,(TRIM('Tabla dinam gestion comercial'!$N:$N)=TRIM($H$4))*('Tabla dinam gestion comercial'!$M:$M<>""))))*3,0)} -> 6 | I21: Mide los leads calificados del territorio durante el período evaluado frente a la meta esperada. La meta se calcula según la cantidad de comerciales del territorio y los meses evaluados, permitiendo reflejar tanto la generación como la gestión efectiva de los leads.
A22: #VALUE! | B22: leads calificados a tiempo | C22: =IF(D22>=90%,"⬤",IF(D22>=75%,"⬤",IF(D22>=60%,"⬤","⬤"))) -> ⬤ | D22: =IF(H22=0,0,IFERROR(G22/H22,0)) -> 0 | E22: 0.9 | F22: 0.1 | G22: =SUMIFS(Leads!$P:$P,Leads!$L:$L,$H$4) -> 0 | H22: {=IFERROR(COUNTA(_xlfn.UNIQUE(_xlfn._xlws.FILTER('Tabla dinam gestion comercial'!$M:$M,(TRIM('Tabla dinam gestion comercial'!$N:$N)=TRIM($H$4))*('Tabla dinam gestion comercial'!$M:$M<>""))))*3,0)} -> 6 | I22: Mide los leads calificados a tiempo frente a la meta esperada del período. La meta se calcula según la cantidad de comerciales del territorio y los meses evaluados, permitiendo reflejar tanto la generación esperada como la oportunidad en la gestión.
A23: #VALUE! | B23: Impacto en clientes (actividades de campo) | C23: =IF(D23>=90%,"⬤",IF(D23>=75%,"⬤",IF(D23>=60%,"⬤","⬤"))) -> ⬤ | D23: =MIN(G23/H23,150%) -> 0.57142857 | E23: 0.9 | F23: 0.1 | G23: =IFERROR(COUNTIF('Act Campo'!$Q$2:$Q$974,$H$4),0) -> 2 | H23: =VLOOKUP(H4,'Tabla dinam gestion comercial'!N:S,6,0) -> 3.5 | I23: Mide el cumplimiento de actividades y parcelas realizadas por los promotores del territorio frente a la meta esperada. Por cada promotor se esperan 3 actividades trimestrales y 0,5 parcelas, con reconocimiento máximo hasta el 150%.
A24: #VALUE! | B24: Hectáreas de cultivos impactados | C24: =IF(D24>=90%,"⬤",IF(D24>=75%,"⬤",IF(D24>=60%,"⬤","⬤"))) -> ⬤ | D24: =IFERROR(MIN(G24/H24,150%),0) -> 0 | E24: 0.9 | F24: 0.05 | G24: =SUMIF(Fincas!$B:$B, $H$4, Fincas!$F:$F) -> 0 | H24: =ROUNDUP(SUMIFS('Tabla dinam gestion comercial'!$T:$T,'Tabla dinam gestion comercial'!$N:$N,$H$4,'Tabla dinam gestion comercial'!$O:$O,"*Promotor*")*3,0) -> 90 | I24: Mide las hectáreas gestionadas en el período frente a la meta del territorio. Cada promotor debe gestionar 30 hectáreas mensuales, equivalentes a 90 por trimestre, con reconocimiento de cumplimiento máximo hasta el 150%.
A25: #VALUE! | B25: Cultivos impactados | C25: =IF(D25>=90%,"⬤",IF(D25>=75%,"⬤",IF(D25>=60%,"⬤","⬤"))) -> ⬤ | D25: =IFERROR(MIN(G25/H25, 1.5), 0) -> 0 | E25: 0.9 | F25: 0.05 | G25: =COUNTIFS(Fincas!$B:$B, $H$4, Fincas!$D:$D, "<>") -> 0 | H25: =IFERROR(ROUNDUP(SUMIFS('Tabla dinam gestion comercial'!$U:$U,'Tabla dinam gestion comercial'!$N:$N,$H$4,'Tabla dinam gestion comercial'!$O:$O,"*PROMOTOR*"),0),0) -> 3 | I25: Mide los cultivos gestionados en el período frente a la meta del territorio. Cada promotor debe gestionar mínimo 1 cultivo mensual, equivalente a 3 por trimestre, con reconocimiento de cumplimiento máximo hasta el 150%.
A26: #VALUE! | B26: Gestión de Cultivos Impactados | C26: =IF(D26>=90%,"⬤",IF(D26>=75%,"⬤",IF(D26>=60%,"⬤","⬤"))) -> ⬤ | D26: =(D24+D25)/2 -> 0 | E26: 0.9 | F26: =F24+F25 -> 0.1
A27: #VALUE! | B27: "Enfócate en las oportunidades de mejora y mantén el ritmo en tus fortalezas." ¡Tú puedes alcanzar tus objetivos! | E27: Requiere mejora (<60%) | G27: En desarrollo (60% -74 %) | H27: Bueno (>=75% - 89%) | I27: Excelente (>=90%)
A30: Oportunidades | D30: Fortalezas | G30: Resumen ejecutivo | I30: Plan de acción sugerido
A31: =IF($N$9>=90,"El territorio tiene el reto de sostener la excelencia alcanzada. Mantener el foco, anticipar desviaciones y compartir las buenas prácticas permitirá conservar este nivel de desempeño.",IF($N$9>=75,"El territorio está cerca del nivel excelente. La oportunidad está en cerrar las brechas pendientes y fortalecer los indicadores que pueden impulsar el resultado global.",IF($N$9>=59,"El territorio cuenta con oportunidades claras de mejora. Enfocar los esfuerzos en los indicadores de menor cumplimiento permitirá avanzar con mayor fuerza en el siguiente período.","El territorio tiene una oportunidad importante de recuperación. Priorizar los indicadores críticos, definir acciones concretas y mantener el acompañamiento permitirá retomar el camino hacia la meta."))) -> El territorio tiene una oportunidad importante de recuperación. Priorizar los indicadores críticos, definir acciones concretas y mantener el acompañamiento permitirá retomar el camino hacia la meta. | D31: =IF($N$9>=90,"Durante el segundo trimestre, el territorio consolida una ejecución sobresaliente. Se destacan la estabilidad de los resultados, la continuidad en la gestión y la capacidad para mantener indicadores clave por encima de la meta al cierre del semestre.",IF($N$9>=75,"El cierre del segundo trimestre muestra una gestión favorable del territorio. Se destacan avances sostenidos en indicadores principales y una base de ejecución que permite proyectar mejoras para el tercer trimestre.",IF($N$9>=59,"En el segundo trimestre se identifican puntos de avance que pueden servir como base para la recuperación. Algunos indicadores muestran capacidad de respuesta del territorio y permiten enfocar mejor las acciones del siguiente período.","Aunque el resultado general del segundo trimestre es bajo, se identifican señales puntuales de gestión que deben conservarse. Estos avances permiten reconocer dónde existe capacidad de reacción y desde allí orientar la recuperación del territorio."))) -> Aunque el resultado general del segundo trimestre es bajo, se identifican señales puntuales de gestión que deben conservarse. Estos avances permiten reconocer dónde existe capacidad de reacción y desde allí orientar la recuperación del territorio. | G31: =IF($N$9>=90,"El territorio cierra el trimestre con un desempeño sobresaliente frente a los objetivos definidos. La gestión refleja enfoque, consistencia y capacidad de ejecución. El reto será sostener este nivel y seguir fortaleciendo los indicadores clave.",IF($N$9>=75,"El territorio presenta un resultado positivo y cercano al nivel esperado. Hay avances importantes que deben mantenerse, junto con el fortalecimiento de los indicadores pendientes para avanzar hacia un desempeño excelente.",IF($N$9>=59,"El trimestre muestra avances parciales y oportunidades claras de mejora. Con mayor foco en los indicadores de mayor impacto, el territorio puede fortalecer su resultado en el siguiente período.","El trimestre representa una oportunidad importante para ajustar la gestión del territorio. Priorizar los indicadores críticos y ejecutar acciones concretas permitirá avanzar hacia una mejor recuperación del desempeño."))) -> El trimestre representa una oportunidad importante para ajustar la gestión del territorio. Priorizar los indicadores críticos y ejecutar acciones concretas permitirá avanzar hacia una mejor recuperación del desempeño. | I31: =IF($N$9>=90,"Estandarizar las buenas prácticas del territorio y replicarlas en los indicadores con mayor impacto. Mantener seguimiento preventivo mensual, revisar alertas tempranas y asegurar continuidad en la ejecución comercial.",IF($N$9>=75,"Construir un plan de cierre de brechas para los indicadores que aún no alcanzan el nivel excelente. Definir responsables, acciones puntuales por indicador y fechas de revisión para mejorar el resultado del siguiente período.",IF($N$9>=59,"Implementar un plan de refuerzo para el territorio. Priorizar los indicadores con menor cumplimiento, organizar una agenda semanal de gestión y hacer seguimiento a los avances con responsables definidos.","Activar un plan de recuperación del territorio con seguimiento semanal. Concentrar la gestión en los indicadores críticos, definir responsables por frente de trabajo, revisar causas del bajo resultado y establecer compromisos de mejora medibles."))) -> Activar un plan de recuperación del territorio con seguimiento semanal. Concentrar la gestión en los indicadores críticos, definir responsables por frente de trabajo, revisar causas del bajo resultado y establecer compromisos de mejora medibles.

Sheet mensual
A1: #VALUE! | C1: Reporte de desempeño comercial - Individual
C2: Reporte de desempeño comercial | H2: Nombre: | J2: Estefania Osorio Usuga
C3: Resumen trimestral | H3: Cargo: | J3: =VLOOKUP(J2,'Tabla dinam gestion comercial'!M:O,3,0) -> PROMOTOR GALAGRO VALLE DE ABURRA
C4: Trimestre 2 | H4: Territorio: | J4: =VLOOKUP(J2,'Tabla dinam gestion comercial'!M:N,2,0) -> GALAGRO VALLE DE ABURRA ANT.
C5: Abril - junio de 2026 | H5: Empresa: | J5: =VLOOKUP(J2,'Tabla dinam gestion comercial'!M:P,4,0) -> GALAGRO
A7: Resultado global
A8: =SUMPRODUCT($D$15:$D$26, $F$15:$F$26) -> 0.27782781
M9: Valor | N9: =A8*100 -> 27.782781 | O9: =ROUND(N9,0)&"%" -> 28%
M10: Restante | N10: =100-N9 -> 72.217219
M11: Oculto | N11: 100
A12: =IF(A8>=90%,"Excelente",IF(A8>=75%,"Destacado",IF(A8>=59%,"En desarrollo","Crítico"))) -> Crítico
A13: Indicadores clave
A14: Indicador | D14: Resultado trimestre | E14: Meta | F14: Peso | G14: Gestión abril | H14: Gestión mayo | I14: Gestión junio | J14: Meta esperada prom. mes | K14: Criterios de medición
A15: #VALUE! | B15: Ejecución visitas | C15: =IF(D15>=90%,"⬤",IF(D15>=75%,"⬤",IF(D15>=60%,"⬤","⬤"))) -> ⬤ | D15: =IFERROR(MIN(100%,SUM(G15:I15)/($J15*3)),0) -> 0.58888889 | E15: 0.9 | F15: 0.1 | G15: =SUMIFS( 'Tabla dinam gestion comercial'!$F:$F, 'Tabla dinam gestion comercial'!$B:$B,$J$2, 'Tabla dinam gestion comercial'!$K:$K,"Abril" ) -> 32 | H15: =SUMIFS( 'Tabla dinam gestion comercial'!$F:$F, 'Tabla dinam gestion comercial'!$B:$B,$J$2, 'Tabla dinam gestion comercial'!$K:$K,"Mayo" ) -> 33 | I15: =SUMIFS( 'Tabla dinam gestion comercial'!$F:$F, 'Tabla dinam gestion comercial'!$B:$B,$J$2, 'Tabla dinam gestion comercial'!$K:$K,"Junio" ) -> 41 | J15: =MIN(2000,SUMIFS('Tabla dinam gestion comercial'!$L:$L,'Tabla dinam gestion comercial'!$B:$B,$J$2)/3) -> 60 | K15: Mide el cumplimiento acumulado de visitas del período. Se suman las visitas realizadas en los tres meses y se comparan contra la meta mensual multiplicada por el número de meses evaluados.
A16: #VALUE! | B16: Cobertura clientes | C16: =IF(D16>=90%,"⬤",IF(D16>=75%,"⬤",IF(D16>=60%,"⬤","⬤"))) -> ⬤ | D16: =IFERROR(MIN(100%,SUM(G16:I16)/($J16*3)),0) -> 1 | E16: 0.9 | F16: 0.1 | G16: =SUMIFS('Tabla dinam gestion comercial'!$D:$D,'Tabla dinam gestion comercial'!$B:$B,$J$2,'Tabla dinam gestion comercial'!$K:$K,"Abril") -> 2 | H16: =SUMIFS('Tabla dinam gestion comercial'!$D:$D,'Tabla dinam gestion comercial'!$B:$B,$J$2,'Tabla dinam gestion comercial'!$K:$K,"Mayo") -> 4 | I16: =SUMIFS('Tabla dinam gestion comercial'!$D:$D,'Tabla dinam gestion comercial'!$B:$B,$J$2,'Tabla dinam gestion comercial'!$K:$K,"Junio") -> 4 | J16: =IFERROR(SUMIFS('Tabla dinam gestion comercial'!$C$2:$C$84,'Tabla dinam gestion comercial'!$B$2:$B$84,$J$2)/3,0)/3 -> 2.6666667 | K16: Mide el cumplimiento acumulado. Se suman las visitas realizadas en los tres meses y se comparan contra la meta esperada para el trimestre. Si el resultado supera la meta, el cumplimiento máximo reconocido es del 100%.
A17: #VALUE! | B17: Nuevos clientes | C17: =IF(D17>=90%,"⬤",IF(D17>=75%,"⬤",IF(D17>=60%,"⬤","⬤"))) -> ⬤ | D17: =IFERROR(AVERAGE(G17/J17,H17/J17,I17/J17),0) -> 0 | E17: 0.9 | F17: 0.1 | G17: =SUMIFS('Tabla dinam gestion comercial'!$I:$I,'Tabla dinam gestion comercial'!$B:$B,$J$2,'Tabla dinam gestion comercial'!$K:$K,"*Abril*") -> 0 | H17: =SUMIFS('Tabla dinam gestion comercial'!$I:$I,'Tabla dinam gestion comercial'!$B:$B,$J$2,'Tabla dinam gestion comercial'!$K:$K,"*Mayo*") -> 0 | I17: =SUMIFS('Tabla dinam gestion comercial'!$I:$I,'Tabla dinam gestion comercial'!$B:$B,$J$2,'Tabla dinam gestion comercial'!$K:$K,"*Junio*") -> 0 | J17: =ROUNDUP(SUMIFS('Tabla dinam gestion comercial'!$H:$H,'Tabla dinam gestion comercial'!$B:$B,$J$2)/12,0) -> 5 | K17: Cuenta clientes nuevos y recuperados que registran una gestión o una venta durante el período. El resultado toma el total acumulado alcanzado y lo compara contra la meta esperada.
A18: Indicador | D18: Resultado trimestre | E18: Meta | F18: Peso | G18: Gestión abril | H18: Gestión mayo | I18: Gestión junio | J18: Meta acum. período | K18: Criterios de medición
A19: #VALUE! | B19: Recomendaciones | C19: =IF(D19>=90%,"⬤",IF(D19>=75%,"⬤",IF(D19>=60%,"⬤","⬤"))) -> ⬤ | D19: =IFERROR(MIN(150%,SUM(G19:I19)/J19),0) -> 0.2585771 | E19: 0.9 | F19: 0.2 | G19: =SUMIFS(Tecnico!$D:$D,Tecnico!$A:$A,$J$4,Tecnico!$K:$K,"Abril") -> 0 | H19: =SUMIFS(Tecnico!$D:$D,Tecnico!$A:$A,$J$4,Tecnico!$K:$K,"Mayo") -> 0 | I19: =SUMIFS(Tecnico!$D:$D,Tecnico!$A:$A,$J$4,Tecnico!$K:$K,"Junio") -> 233603100 | J19: =SUMIFS(Tecnico!$C:$C,Tecnico!$A:$A,$J$4) -> 903417581 | K19: Suma las recomendaciones generadas durante el período evaluado y compara ese total contra la meta acumulada. El resultado muestra el porcentaje de cumplimiento alcanzado frente a la meta del trimestre.
A20: #VALUE! | B20: Referencias | C20: =IF(D20>=90%,"⬤",IF(D20>=75%,"⬤",IF(D20>=60%,"⬤","⬤"))) -> ⬤ | D20: =IFERROR(((G20+H20+I20)/J20),"0") -> 0.10080645 | E20: 0.9 | F20: 0.1 | G20: =SUMIFS(Tecnico!$J:$J,Tecnico!$A:$A,$J$4,Tecnico!$K:$K,"Abril") -> 0 | H20: =SUMIFS(Tecnico!$J:$J,Tecnico!$A:$A,$J$4,Tecnico!$K:$K,"Mayo") -> 0 | I20: =SUMIFS(Tecnico!$J:$J,Tecnico!$A:$A,$J$4,Tecnico!$K:$K,"Junio") -> 25 | J20: =SUMIFS(Tecnico!$H:$H,Tecnico!$A:$A,$J$4)/3 -> 248 | K20: Mide el cumplimiento de referencias gestionadas frente a la meta esperada del período. Se suman las referencias generadas en los meses evaluados y se comparan contra la meta (SKU activas). El resultado muestra el porcentaje de cumplimiento alcanzado.
A21: Indicador | D21: Resultado trimestre | E21: Meta | F21: Peso | G21: Gestión abril | H21: Gestión mayo | I21: Gestión junio | J21: Meta acum. período | K21: Criterios de medición
A22: #VALUE! | B22: Leads calificados | C22: =IF(D22>=90%,"⬤",IF(D22>=75%,"⬤",IF(D22>=60%,"⬤","⬤"))) -> ⬤ | D22: =IFERROR(SUM(G22:I22)/J22,0%) -> 0 | E22: 0.9 | F22: 0.1 | G22: =IFERROR(SUMIFS(Leads!$D:$D,Leads!$C:$C,$J$2,Leads!$I:$I,"Abril"),0) -> 0 | H22: =IFERROR(SUMIFS(Leads!$D:$D,Leads!$C:$C,$J$2,Leads!$I:$I,"Mayo"),0) -> 0 | I22: =IFERROR(SUMIFS(Leads!$D:$D,Leads!$C:$C,$J$2,Leads!$I:$I,"Junio"),0) -> 0 | J22: =MAX(1,IFERROR(SUMIFS(Leads!$D:$D,Leads!$C:$C,$J$2,Leads!$I:$I,"Enero"),0))+MAX(1,IFERROR(SUMIFS(Leads!$D:$D,Leads!$C:$C,$J$2,Leads!$I:$I,"Febrero"),0))+MAX(1,IFERROR(SUMIFS(Leads!$D:$D,Leads!$C:$C,$J$2,Leads!$I:$I,"Marzo"),0)) -> 3 | K22: Mide la generación de leads frente a la meta esperada. La meta considera mínimo 1 lead por mes evaluado y aumenta según los leads generados, con el fin de incentivar la creación constante de oportunidades comerciales. Si no se generan leads, el cumplimiento es 0%.
A23: #VALUE! | B23: Leads calificados a tiempo | C23: =IF(D23>=90%,"⬤",IF(D23>=75%,"⬤",IF(D23>=60%,"⬤","⬤"))) -> ⬤ | D23: =IFERROR(SUM(G23:I23)/J23,0%) -> 0 | E23: 0.9 | F23: 0.1 | G23: =IFERROR(SUMIFS(Leads!$E:$E,Leads!$C:$C,$J$2,Leads!$I:$I,"Abril"),0) -> 0 | H23: =IFERROR(SUMIFS(Leads!$E:$E,Leads!$C:$C,$J$2,Leads!$I:$I,"Mayo"),0) -> 0 | I23: =IFERROR(SUMIFS(Leads!$E:$E,Leads!$C:$C,$J$2,Leads!$I:$I,"Junio"),0) -> 0 | J23: =MAX(1,IFERROR(SUMIFS(Leads!$D:$D,Leads!$C:$C,$J$2,Leads!$I:$I,"Enero"),0))+MAX(1,IFERROR(SUMIFS(Leads!$D:$D,Leads!$C:$C,$J$2,Leads!$I:$I,"Febrero"),0))+MAX(1,IFERROR(SUMIFS(Leads!$D:$D,Leads!$C:$C,$J$2,Leads!$I:$I,"Marzo"),0)) -> 3 | K23: Mide el porcentaje de leads que fueron calificados dentro del tiempo establecido (48 horas después de generado). Se compara la cantidad de leads calificados oportunamente frente al total de leads que debían ser gestionados en el período.
A24: #VALUE! | B24: Impacto en clientes (Actividades de campo) | C24: =IF(D24>=90%,"⬤",IF(D24>=75%,"⬤",IF(D24>=60%,"⬤","⬤"))) -> ⬤ | D24: =MIN(IFERROR(SUM(G24:I24)/J24,0%),150%) -> 0.57142857 | E24: 0.9 | F24: 0.1 | G24: {=SUMPRODUCT((TRIM(CLEAN('Act Campo'!$Q$2:$Q$974))=TRIM(CLEAN($J$4)))*(LOWER(TRIM(CLEAN('Act Campo'!$AF$2:$AF$974)))="abril"))} -> 2 | H24: =COUNTIFS('Act Campo'!$Q$2:$Q$974,$J$4,'Act Campo'!$AF$2:$AF$974,"Mayo") -> 0 | I24: =COUNTIFS('Act Campo'!$Q$2:$Q$974,$J$4,'Act Campo'!$AF$2:$AF$974,"Junio") -> 0 | J24: =IFERROR(VLOOKUP(J2,'Tabla dinam gestion comercial'!$M:$S,7,0),0) -> 3.5 | K24: Mide el cumplimiento de actividades y parcelas frente a la meta del territorio. Por cada promotor se esperan 3 actividades trimestrales y 0,5 parcelas, con reconocimiento máximo hasta el 150%.
A25: #VALUE! | B25: Hectáreas de cultivos impactados | C25: =IF(D25>=90%,"⬤",IF(D25>=75%,"⬤",IF(D25>=60%,"⬤","⬤"))) -> ⬤ | D25: =MIN(IFERROR(SUM(G25:I25)/J25,0%),150%) -> 0 | E25: 0.9 | F25: 0.05 | G25: =SUMIFS(Fincas!$F:$F,Fincas!$B:$B,$J$4,Fincas!$G:$G,"Abril") -> 0 | H25: =SUMIFS(Fincas!$F:$F,Fincas!$B:$B,$J$4,Fincas!$G:$G,"Mayo") -> 0 | I25: =SUMIFS(Fincas!$F:$F,Fincas!$B:$B,$J$4,Fincas!$G:$G,"Junio") -> 0 | J25: =ROUNDUP(_xlfn.MAXIFS('Tabla dinam gestion comercial'!$T:$T,'Tabla dinam gestion comercial'!$M:$M,$J$2)*3,0) -> 90 | K25: Mide las hectáreas gestionadas en el período frente a la meta del territorio. Cada promotor debe gestionar 30 hectáreas mensuales, equivalentes a 90 por trimestre, con reconocimiento de cumplimiento máximo hasta el 150%.
A26: #VALUE! | B26: Cultivos impactados | C26: =IF(D26>=90%,"⬤",IF(D26>=75%,"⬤",IF(D26>=60%,"⬤","⬤"))) -> ⬤ | D26: =MIN(IFERROR(SUM(G26:I26)/J26,0%),150%) -> 0 | E26: 0.9 | F26: 0.05 | G26: =COUNTIFS(Fincas!$B:$B,$J$4,Fincas!$D:$D,"<>",Fincas!$G:$G,"Abril") -> 0 | H26: =COUNTIFS(Fincas!$B:$B,$J$4,Fincas!$D:$D,"<>",Fincas!$G:$G,"Mayo") -> 0 | I26: =COUNTIFS(Fincas!$B:$B,$J$4,Fincas!$D:$D,"<>",Fincas!$G:$G,"Junio") -> 0 | J26: =ROUNDUP(SUMIFS('Tabla dinam gestion comercial'!$U:$U,'Tabla dinam gestion comercial'!$M:$M,$J$2),0) -> 3 | K26: Mide los cultivos gestionados en el período frente a la meta del territorio. Cada promotor debe gestionar mínimo 1 cultivo mensual, equivalente a 3 por trimestre, con reconocimiento de cumplimiento máximo hasta el 150%.
A27: #VALUE! | B27: Gestión de Cultivos Impactados | C27: =IF(D27>=90%,"⬤",IF(D27>=75%,"⬤",IF(D27>=60%,"⬤","⬤"))) -> ⬤ | D27: =(D25+D26)/2 -> 0 | E27: 0.9
A28: #VALUE! | B28: "Enfócate en las oportunidades de mejora y mantén el ritmo en tus fortalezas." ¡Tú puedes alcanzar tus objetivos! | G28: Requiere mejora (<60%) | H28: En desarrollo (60% - 74%) | J28: Bueno (>=75% - 89%) | K28: Excelente (>=90%)
A31: Oportunidades | D31: Fortalezas | H31: Resumen ejecutivo | K31: Plan de acción sugerido
A32: =IF($N$9>=90,"El reto para el siguiente período es sostener el nivel alcanzado y evitar desviaciones. Se recomienda revisar los indicadores cercanos al límite y mantener seguimiento sobre los frentes de mayor impacto.",IF($N$9>=75,"La principal oportunidad está en cerrar las brechas que impiden llegar al nivel excelente. Para el tercer trimestre, será clave reforzar la ejecución y dar seguimiento a los indicadores pendientes.",IF($N$9>=59,"El cierre del semestre evidencia brechas que deben atenderse con prioridad. Se recomienda concentrar la gestión en los indicadores de menor cumplimiento y ajustar la planificación del siguiente trimestre.","El resultado exige una recuperación enfocada para el tercer trimestre. Es necesario priorizar los indicadores críticos, definir responsables y realizar seguimiento frecuente a las acciones de mejora."))) -> El resultado exige una recuperación enfocada para el tercer trimestre. Es necesario priorizar los indicadores críticos, definir responsables y realizar seguimiento frecuente a las acciones de mejora. | D32: =IF($N$9>=90,"Se consolidan fortalezas importantes en la gestión del territorio. El resultado refleja disciplina, continuidad en la ejecución y buen desempeño en los indicadores de mayor impacto durante el cierre del semestre.",IF($N$9>=75,"El trimestre muestra una base de gestión positiva. Se evidencian avances en indicadores clave y una ejecución que permite proyectar un mejor desempeño para el siguiente período.",IF($N$9>=59,"Aunque persisten oportunidades de mejora, se identifican avances que pueden servir como punto de apoyo para el cierre de brechas. La gestión debe concentrarse en replicar los indicadores con mejor comportamiento.","A pesar del resultado bajo, algunos indicadores muestran señales de avance. Estos puntos deben tomarse como base para orientar la recuperación y enfocar mejor la gestión del siguiente trimestre."))) -> A pesar del resultado bajo, algunos indicadores muestran señales de avance. Estos puntos deben tomarse como base para orientar la recuperación y enfocar mejor la gestión del siguiente trimestre. | H32: =IF($N$9>=90,"El segundo trimestre cierra con un resultado destacado y una gestión consistente frente a los objetivos. El foco para el siguiente período será conservar la disciplina, proteger los indicadores de mayor impacto y sostener el desempeño alcanzado.",IF($N$9>=75,"El trimestre muestra un avance favorable y una gestión cercana al nivel esperado. Para el siguiente período, será clave cerrar las brechas pendientes, reforzar la ejecución comercial y mantener mayor regularidad en los indicadores.",IF($N$9>=59,"El resultado evidencia avances parciales, pero aún requiere mayor consistencia en la gestión. El cierre del semestre debe servir para ajustar prioridades, fortalecer el seguimiento y enfocar los esfuerzos en los indicadores con menor cumplimiento.","El cierre del segundo trimestre muestra desviaciones relevantes frente a la meta. Se requiere revisar la gestión del período, identificar las causas principales y activar acciones concretas para recuperar el desempeño en el siguiente trimestre."))) -> El cierre del segundo trimestre muestra desviaciones relevantes frente a la meta. Se requiere revisar la gestión del período, identificar las causas principales y activar acciones concretas para recuperar el desempeño en el siguiente trimestre. | K32: =IF($N$9>=90,"Mantener el nivel alcanzado durante el cierre del semestre. Revisar indicadores sensibles, asegurar continuidad en las buenas prácticas y preparar acciones preventivas para el tercer trimestre.",IF($N$9>=75,"Cerrar las brechas que aún limitan el paso al nivel excelente. Definir acciones concretas, responsables y fechas de seguimiento para fortalecer el desempeño del tercer trimestre.",IF($N$9>=59,"Reajustar el plan de trabajo para el siguiente trimestre. Priorizar los indicadores con menor avance, fortalecer la planificación semanal y hacer seguimiento a los compromisos definidos.","Activar un plan de recuperación para el tercer trimestre. Priorizar los indicadores críticos, definir responsables, solicitar acompañamiento y realizar seguimiento semanal."))) -> Activar un plan de recuperación para el tercer trimestre. Priorizar los indicadores críticos, definir responsables, solicitar acompañamiento y realizar seguimiento semanal.

Sheet Trimestre
A1: #VALUE! | D1: Reporte de desempeño comercial - Territorio
D2: Reporte De Desempeño Comercial | G2: Nombre | H2: Brarlyn Steven Garcia Castro
D3: Resumen Trimestral | G3: Cargo: | H3: =VLOOKUP(H2,'Tabla dinam gestion comercial'!M:O,3,0) -> PROMOTOR GALAGRO ORIENTE B ANT
D4: Trimestre 1 | G4: Territorio | H4: =VLOOKUP(H2,'Tabla dinam gestion comercial'!M:N,2,0) -> GALAGRO ORIENTE B ANT.
D5: Abril - junio de 2026 | G5: Empresa: | H5: =VLOOKUP(H2,'Tabla dinam gestion comercial'!M:P,4,0) -> GALAGRO
A6: Resultado Global
A7: =SUMPRODUCT($D$14:$D$24, $F$14:$F$24) -> 0.25570164
J8: Valor | K8: =A7*100 -> 25.570164 | L8: =ROUND(K8,0)&"%" -> 26%
J9: Restante | K9: =100-K8 -> 74.429836
J10: Oculto | K10: 100
A11: =IF(A7>=90%,"Excelente",IF(A7>=75%,"Destacado",IF(A7>=59%,"En desarrollo","Crítico"))) -> Crítico
A12: INDICADORES CLAVE
A13: Indicador | D13: Cumplimiento | E13: Meta | F13: Peso | G13: Gestión real Prom X 3 meses | H13: Meta Esperada prom mes | I13: Criterios de medición
A14: #VALUE! | B14: Ejecución Visitas | C14: =IF(D14>=90%,"⬤",IF(D14>=75%,"⬤",IF(D14>=60%,"⬤","⬤"))) -> ⬤ | D14: =IFERROR(MIN(100%,G14/H14),0) -> 0.4 | E14: 0.9 | F14: 0.1 | G14: =IFERROR(SUMIFS('Tabla dinam gestion comercial'!$F:$F,'Tabla dinam gestion comercial'!$B:$B,$H$2)/3,0) -> 24 | H14: =MIN(2000,SUMIFS('Tabla dinam gestion comercial'!$L:$L,'Tabla dinam gestion comercial'!$B:$B,$H$2)/3) -> 60 | I14: Compara las visitas realizadas con la meta mensual. Cumplir o superar la meta equivale a 100%. El resultado es el promedio de los meses evaluados.
A15: #VALUE! | B15: Cobertura Clientes | C15: =IF(D15>=90%,"⬤",IF(D15>=75%,"⬤",IF(D15>=60%,"⬤","⬤"))) -> ⬤ | D15: =IFERROR(MIN(100%,G15/H15),0) -> 0.62589928 | E15: 0.9 | F15: 0.1 | G15: =IFERROR(SUMIFS('Tabla dinam gestion comercial'!$D:$D,'Tabla dinam gestion comercial'!$B:$B,$H$2)/3,0) -> 29 | H15: =IFERROR(SUMIFS('Tabla dinam gestion comercial'!$C$2:$C$84,'Tabla dinam gestion comercial'!$B$2:$B$84,$H$2)/3,0)/3 -> 46.333333 | I15: Mide cuántos clientes del territorio fueron visitados frente a la meta mensual asignada. Se calcula con el promedio de clientes visitados durante los meses evaluados y se compara contra la meta de cobertura. La meta no se acumula entre meses.
A16: #VALUE! | B16: Nuevos Clientes | C16: =IF(D16>=90%,"⬤",IF(D16>=75%,"⬤",IF(D16>=60%,"⬤","⬤"))) -> ⬤ | D16: =G16/H16 -> 0 | E16: 0.9 | F16: 0.1 | G16: =SUMIFS('Tabla dinam gestion comercial'!$I:$I,'Tabla dinam gestion comercial'!$B:$B,$H$2)/3 -> 0 | H16: =ROUNDUP(SUMIFS('Tabla dinam gestion comercial'!$H:$H,'Tabla dinam gestion comercial'!$B:$B,$H$2)/12,0) -> 3 | I16: Cuenta los clientes recuperados y los clientes nuevos que registran una gestión o una venta. La meta mensual corresponde a la meta anual dividida entre 12 meses.
A17: Indicador | D17: Cumplimiento | E17: Meta | F17: Peso | G17: Gestión Real | H17: Meta acum. período | I17: Criterios de medición
A18: #VALUE! | B18: Recomendados | C18: =IF(D18>=90%,"⬤",IF(D18>=75%,"⬤",IF(D18>=60%,"⬤","⬤"))) -> ⬤ | D18: =IFERROR((G18/H18),"0") -> 0.00031917001 | E18: 0.9 | F18: 0.2 | G18: =SUMIFS(Tecnico!$D:$D,Tecnico!$A:$A,$H$4) -> 936500 | H18: =SUMIFS(Tecnico!$C:$C,Tecnico!$A:$A,$H$4) -> 2934172884 | I18: Suma las recomendaciones generadas en enero, febrero y marzo, y compara ese total contra la meta acumulada del período. El resultado muestra qué porcentaje de la meta trimestral se alcanzó.
A19: #VALUE! | B19: Referencias | C19: =IF(D19>=90%,"⬤",IF(D19>=75%,"⬤",IF(D19>=60%,"⬤","⬤"))) -> ⬤ | D19: =IF(AND(G19=0, H19=0), 100%, IF(G19=0, 0%, G19/H19)) -> 0.02016129 | E19: 0.9 | F19: 0.1 | G19: =SUMIFS(Tecnico!$J:$J,Tecnico!$A:$A,$H$4) -> 5 | H19: =SUMIFS(Tecnico!$H:$H,Tecnico!$A:$A,$H$4)/3 -> 248 | I19: Mide cuántas referencias se gestionaron frente a la meta esperada. Se suman las referencias de enero, febrero y marzo, y se comparan contra la meta promedio del trimestre.
A20: #VALUE! | B20: leads Calificados | C20: =IF(D20>=90%,"⬤",IF(D20>=75%,"⬤",IF(D20>=60%,"⬤","⬤"))) -> ⬤ | D20: =IF(H20=0,0,IFERROR(G20/H20,0)) -> 0 | E20: 0.9 | F20: 0.1 | G20: =IFERROR(VLOOKUP(H2,Leads!C:H,2,0),"0") -> 0 | H20: =MAX(1,IFERROR(SUMIFS(Leads!$D:$D,Leads!$C:$C,$H$2,Leads!$I:$I,"Enero"),0))+MAX(1,IFERROR(SUMIFS(Leads!$D:$D,Leads!$C:$C,$H$2,Leads!$I:$I,"Febrero"),0))+MAX(1,IFERROR(SUMIFS(Leads!$D:$D,Leads!$C:$C,$H$2,Leads!$I:$I,"Marzo"),0)) -> 3 | I20: Mide cuántos de los leads creados en el período fueron gestionados. El resultado corresponde al porcentaje de atención sobre el total de leads generados.
A21: #VALUE! | B21: leads Calificados A Tiempo | C21: =IF(D21>=90%,"⬤",IF(D21>=75%,"⬤",IF(D21>=60%,"⬤","⬤"))) -> ⬤ | D21: =IF(H21=0,0,IFERROR(G21/H21,0)) -> 0 | E21: 0.9 | F21: 0.1 | G21: =IFERROR(VLOOKUP(H2,Leads!$K:$P,6,0),0) -> 0 | H21: =MAX(1,IFERROR(SUMIFS(Leads!$D:$D,Leads!$C:$C,$H$2,Leads!$I:$I,"Enero"),0))+MAX(1,IFERROR(SUMIFS(Leads!$D:$D,Leads!$C:$C,$H$2,Leads!$I:$I,"Febrero"),0))+MAX(1,IFERROR(SUMIFS(Leads!$D:$D,Leads!$C:$C,$H$2,Leads!$I:$I,"Marzo"),0)) -> 3 | I21: Mide el porcentaje de leads que fueron calificados dentro del tiempo establecido. Se compara la cantidad de leads calificados oportunamente frente al total de leads que debían ser gestionados en el período.
A22: #VALUE! | B22: Impacto en clientes (Actividades de Campo) | C22: =IF(D22>=90%,"⬤",IF(D22>=75%,"⬤",IF(D22>=60%,"⬤","⬤"))) -> ⬤ | D22: =MIN(G22/H22,150%) -> 0.57142857 | E22: 0.9 | F22: 0.1 | G22: =COUNTIFS('Act Campo'!$Q$2:$Q$974,$H$4,'Act Campo'!$AF$2:$AF$974,"Abril") +COUNTIFS('Act Campo'!$Q$2:$Q$974,$H$4,'Act Campo'!$AF$2:$AF$974,"Mayo") +COUNTIFS('Act Campo'!$Q$2:$Q$974,$H$4,'Act Campo'!$AF$2:$AF$974,"Junio") -> 2 | H22: =VLOOKUP(H4,'Tabla dinam gestion comercial'!N:S,6,0) -> 3.5 | I22: Mide el cumplimiento de actividades y parcelas frente a la meta del territorio. Por cada promotor se esperan 3 actividades trimestrales y 0,5 parcelas, con reconocimiento máximo hasta el 150%
A23: #VALUE! | B23: Hectareas Cultivos impactados | C23: =IF(D23>=90%,"⬤",IF(D23>=75%,"⬤",IF(D23>=60%,"⬤","⬤"))) -> ⬤ | D23: =MIN(G23/H23,150%) -> 0.37777778 | E23: 0.9 | F23: 0.05 | G23: =SUMIF(Fincas!$B:$B, $H$4, Fincas!$F:$F) -> 34 | H23: =ROUNDUP(_xlfn.MAXIFS('Tabla dinam gestion comercial'!$T:$T,'Tabla dinam gestion comercial'!$M:$M,$H$2)*3,0) -> 90 | I23: Mide las hectáreas gestionadas en el período frente a la meta del territorio. Cada promotor debe gestionar 30 hectáreas mensuales, equivalentes a 90 por trimestre, con reconocimiento de cumplimiento máximo hasta el 150%.
A24: #VALUE! | B24: Cultivos impactados | C24: =IF(D24>=90%,"⬤",IF(D24>=75%,"⬤",IF(D24>=60%,"⬤","⬤"))) -> ⬤ | D24: =IFERROR(MIN(G24/H24, 1.5), 0) -> 1.5 | E24: 0.9 | F24: 0.05 | G24: =COUNTIFS(Fincas!$B:$B, $H$4, Fincas!$D:$D, "<>") -> 7 | H24: =ROUNDUP(SUMIFS('Tabla dinam gestion comercial'!$U:$U,'Tabla dinam gestion comercial'!$M:$M,$H$2),0) -> 3 | I24: Mide los cultivos gestionados en el período frente a la meta del territorio. Cada promotor debe gestionar mínimo 1 cultivo mensual, equivalente a 3 por trimestre, con reconocimiento de cumplimiento máximo hasta el 150%.
A25: #VALUE! | B25: "Enfocate en las oportunidades de mejora y mantén el ritmo en tus fortalezas." ¡Tu puedes alcanzar tus objetivos! | E25: Requiere mejora (<60%) | G25: En Desarrollo (60% - 74 %) | H25: Bueno (>=75% - 89%) | I25: Excelente (>=90%)
A28: Oportunidades | D28: Fortalezas | G28: Resumen Ejecutivo | I28: Plan de acción sugerido
A29: =IF($L$8>=90,"El reto del territorio es sostener el nivel alcanzado y anticipar posibles desviaciones. Se recomienda revisar los indicadores cercanos al límite y mantener control sobre los frentes de mayor impacto.",IF($L$8>=75,"La principal oportunidad está en cerrar las brechas que impiden llegar al nivel excelente. Es clave ajustar la ejecución del territorio y priorizar los indicadores pendientes.",IF($L$8>=59,"El territorio debe concentrarse en los indicadores con menor cumplimiento. Reforzar la planificación, priorizar acciones de impacto y hacer seguimiento a los compromisos permitirá mejorar el resultado general.", "La prioridad del territorio es recuperar los indicadores críticos. Se requiere definir acciones concretas, responsables y seguimiento frecuente para mejorar el cumplimiento."))) -> El reto del territorio es sostener el nivel alcanzado y anticipar posibles desviaciones. Se recomienda revisar los indicadores cercanos al límite y mantener control sobre los frentes de mayor impacto. | D29: =IF($N$9>=90,"Se consolidan fortalezas importantes en la gestión del territorio. El resultado refleja disciplina, continuidad en la ejecución y buen desempeño en los indicadores de mayor impacto durante el cierre del semestre.",IF($N$9>=75,"El trimestre muestra una base de gestión positiva. Se evidencian avances en indicadores clave y una ejecución que permite proyectar un mejor desempeño para el siguiente período.",IF($N$9>=59,"Aunque persisten oportunidades de mejora, se identifican avances que pueden servir como punto de apoyo para el cierre de brechas. La gestión debe concentrarse en replicar los indicadores con mejor comportamiento.","A pesar del resultado bajo, algunos indicadores muestran señales de avance. Estos puntos deben tomarse como base para orientar la recuperación y enfocar mejor la gestión del siguiente trimestre."))) -> A pesar del resultado bajo, algunos indicadores muestran señales de avance. Estos puntos deben tomarse como base para orientar la recuperación y enfocar mejor la gestión del siguiente trimestre. | G29: =IF($N$9>=90,"El segundo trimestre cierra con un resultado destacado y una gestión consistente frente a los objetivos. El foco para el siguiente período será conservar la disciplina, proteger los indicadores de mayor impacto y sostener el desempeño alcanzado.",IF($N$9>=75,"El trimestre muestra un avance favorable y una gestión cercana al nivel esperado. Para el siguiente período, será clave cerrar las brechas pendientes, reforzar la ejecución comercial y mantener mayor regularidad en los indicadores.",IF($N$9>=59,"El resultado evidencia avances parciales, pero aún requiere mayor consistencia en la gestión. El cierre del semestre debe servir para ajustar prioridades, fortalecer el seguimiento y enfocar los esfuerzos en los indicadores con menor cumplimiento.","El cierre del segundo trimestre muestra desviaciones relevantes frente a la meta. Se requiere revisar la gestión del período, identificar las causas principales y activar acciones concretas para recuperar el desempeño en el siguiente trimestre."))) -> El cierre del segundo trimestre muestra desviaciones relevantes frente a la meta. Se requiere revisar la gestión del período, identificar las causas principales y activar acciones concretas para recuperar el desempeño en el siguiente trimestre. | I29: =IF($N$9>=90,"Mantener el nivel alcanzado durante el cierre del semestre. Revisar indicadores sensibles, asegurar continuidad en las buenas prácticas y preparar acciones preventivas para el tercer trimestre.",IF($N$9>=75,"Cerrar las brechas que aún limitan el paso al nivel excelente. Definir acciones concretas, responsables y fechas de seguimiento para fortalecer el desempeño del tercer trimestre.",IF($N$9>=59,"Reajustar el plan de trabajo para el siguiente trimestre. Priorizar los indicadores con menor avance, fortalecer la planificación semanal y hacer seguimiento a los compromisos definidos.","Activar un plan de recuperación para el tercer trimestre. Priorizar los indicadores críticos, definir responsables, solicitar acompañamiento y realizar seguimiento semanal."))) -> Activar un plan de recuperación para el tercer trimestre. Priorizar los indicadores críticos, definir responsables, solicitar acompañamiento y realizar seguimiento semanal.

Sheet Fincas
A1: Unidad de Negocio | B1: des_territorio | C1: atr_desc_empleado | D1: atr_cultivo_texto | E1: # Fincas | F1: Héctareas | G1: Mes | J1: Valores
A2: GALAGRO ANTIOQUIA | B2: GALAGRO ORIENTE A ANT. | C2: Geovanny Andres Monsalve Garcia | D2: Flores y Follajes | E2: 1 | F2: 1 | G2: Abril | I2: Territorio | J2: Suma de Meta hectareas | K2: Suma de cultivos
A3: GALAGRO ANTIOQUIA | B3: GALAGRO ORIENTE A ANT. | C3: Geovanny Andres Monsalve Garcia | D3: Fresa | E3: 3 | F3: 6 | G3: Abril | I3: (en blanco)
A4: GALAGRO ANTIOQUIA | B4: GALAGRO ORIENTE A ANT. | C4: Geovanny Andres Monsalve Garcia | D4: Frijol | E4: 1 | F4: 1 | G4: Abril | I4: GALAGRO ANTIOQUIA DIRECCIÓN | J4: 840 | K4: 84
A5: GALAGRO ANTIOQUIA | B5: GALAGRO ORIENTE A ANT. | C5: Geovanny Andres Monsalve Garcia | D5: Frutales Varios | E5: 1 | F5: 3 | G5: Abril | I5: GALAGRO BAJO CAUCA ANT. | J5: 30 | K5: 3
A6: GALAGRO ANTIOQUIA | B6: GALAGRO ORIENTE A ANT. | C6: Geovanny Andres Monsalve Garcia | D6: Hortensia | E6: 3 | F6: 10 | G6: Abril | I6: GALAGRO CORDOBA ANT. | J6: 60 | K6: 6
A7: GALAGRO ANTIOQUIA | B7: GALAGRO ORIENTE A ANT. | C7: Geovanny Andres Monsalve Garcia | D7: Tomate | E7: 1 | F7: 4 | G7: Abril | I7: GALAGRO URABA ANT. | J7: 120 | K7: 12
A8: GALAGRO ANTIOQUIA | B8: GALAGRO ORIENTE A ANT. | C8: Geovanny Andres Monsalve Garcia | D8: Tomate chonto | E8: 1 | F8: 1 | G8: Abril | I8: GALAGRO NORDESTE Y MAG. MEDIO ANT. | J8: 30 | K8: 3
A9: GALAGRO ANTIOQUIA | B9: GALAGRO ORIENTE B ANT. | C9: Norbey Fernando Montoya Grajales | D9: Habichuela | E9: 1 | F9: 2 | G9: Abril | I9: GALAGRO NORTE ANT. | J9: 120 | K9: 12
A10: GALAGRO ANTIOQUIA | B10: GALAGRO ORIENTE B ANT. | C10: Norbey Fernando Montoya Grajales | D10: Lechuga | E10: 1 | F10: 1 | G10: Abril | I10: GALAGRO ORIENTE B ANT. | J10: 120 | K10: 12
A11: GALAGRO ANTIOQUIA | B11: GALAGRO ORIENTE B ANT. | C11: Norbey Fernando Montoya Grajales | D11: Papa Criolla | E11: 1 | F11: 1 | G11: Abril | I11: GALAGRO VALLE DE ABURRA ANT. | J11: 90 | K11: 9
A12: GALAGRO ANTIOQUIA | B12: GALAGRO ORIENTE B ANT. | C12: Norbey Fernando Montoya Grajales | D12: Pimentón | E12: 2 | F12: 16 | G12: Abril | I12: GALAGRO ORIENTE A ANT. | J12: 120 | K12: 12
A13: GALAGRO ANTIOQUIA | B13: GALAGRO ORIENTE B ANT. | C13: Norbey Fernando Montoya Grajales | D13: Tomate Invernadero | E13: 1 | F13: 5 | G13: Abril | I13: GALAGRO SUROESTE ANT. | J13: 120 | K13: 12
A14: GALAGRO ANTIOQUIA | B14: GALAGRO NORTE ANT. | C14: Miguel Andrés León Díaz | D14: Pasto Clima Frío | E14: 4 | F14: 174 | G14: Mayo | I14: GALAGRO OFICINA ANT. | J14: 30 | K14: 3
A15: GALAGRO ANTIOQUIA | B15: GALAGRO ORIENTE A ANT. | C15: Geovanny Andres Monsalve Garcia | D15: Arveja | E15: 1 | F15: 1 | G15: Mayo | I15: Total general | J15: 1680 | K15: 168
A16: GALAGRO ANTIOQUIA | B16: GALAGRO ORIENTE A ANT. | C16: Geovanny Andres Monsalve Garcia | D16: Crisantemo | E16: 1 | F16: 3 | G16: Mayo
A17: GALAGRO ANTIOQUIA | B17: GALAGRO ORIENTE A ANT. | C17: Geovanny Andres Monsalve Garcia | D17: Fresa | E17: 2 | F17: 5 | G17: Mayo | I17: GALAGRO ANTIOQUIA DIRECCIÓN | J17: Yuri Andrea Garro Sánchez
A18: GALAGRO ANTIOQUIA | B18: GALAGRO ORIENTE A ANT. | C18: Geovanny Andres Monsalve Garcia | D18: Frutales Varios | E18: 1 | F18: 3 | G18: Mayo | I18: GALAGRO BAJO CAUCA ANT. | J18: Yeison Antonio Arenilla Diaz
A19: GALAGRO ANTIOQUIA | B19: GALAGRO ORIENTE A ANT. | C19: Geovanny Andres Monsalve Garcia | D19: Hortensia | E19: 5 | F19: 13 | G19: Mayo | I19: GALAGRO CORDOBA ANT. | J19: Karen Paola Hernández Pacheco
A20: GALAGRO ANTIOQUIA | B20: GALAGRO ORIENTE B ANT. | C20: Norbey Fernando Montoya Grajales | D20: Tomate de mesa (aliño) | E20: 1 | F20: 3 | G20: Mayo | I20: GALAGRO CORDOBA ANT. | J20: (Vacante) Karen Paola Hernandez Pacheco
A21: GALAGRO ANTIOQUIA | B21: GALAGRO NORTE ANT. | C21: Miguel Andrés León Díaz | D21: Papa Capira | E21: 1 | F21: 30 | G21: Junio | I21: GALAGRO NORDESTE Y MAG. MEDIO ANT. | J21: (vacante) Maria Alejandra Duque Laverde
A22: GALAGRO ANTIOQUIA | B22: GALAGRO ORIENTE A ANT. | C22: Geovanny Andres Monsalve Garcia | D22: Aguacate Hass | E22: 2 | F22: 42 | G22: Junio | I22: GALAGRO NORTE ANT. | J22: Luisa Fernanda Quiceno Restrepo
A23: GALAGRO ANTIOQUIA | B23: GALAGRO ORIENTE A ANT. | C23: Geovanny Andres Monsalve Garcia | D23: Crisantemo | E23: 1 | F23: 5 | G23: Junio | I23: GALAGRO NORTE ANT. | J23: Miguel Andrés León Díaz
A24: GALAGRO ANTIOQUIA | B24: GALAGRO ORIENTE A ANT. | C24: Geovanny Andres Monsalve Garcia | D24: Fresa | E24: 3 | F24: 6 | G24: Junio | I24: GALAGRO ORIENTE A ANT. | J24: Geovanny Andres Monsalve Garcia
A25: GALAGRO ANTIOQUIA | B25: GALAGRO ORIENTE A ANT. | C25: Geovanny Andres Monsalve Garcia | D25: Hortensia | E25: 6 | F25: 13 | G25: Junio | I25: GALAGRO ORIENTE A ANT. | J25: Alexander Marulanda Vera
A26: GALAGRO ANTIOQUIA | B26: GALAGRO ORIENTE A ANT. | C26: Geovanny Andres Monsalve Garcia | D26: Tomate chonto | E26: 1 | F26: 8 | G26: Junio | I26: GALAGRO ORIENTE B ANT. | J26: Norbey Fernando Montoya Grajales
A27: GALAGRO ANTIOQUIA | B27: GALAGRO ORIENTE B ANT. | C27: Norbey Fernando Montoya Grajales | D27: Tomate de mesa (aliño) | E27: 2 | F27: 6 | G27: Junio | I27: GALAGRO ORIENTE B ANT. | J27: Brarlyn Steven Garcia Castro
A28: GALAGRO ANTIOQUIA | B28: GALAGRO SUROESTE ANT. | C28: John Álvaro Correa Castaño | D28: Aguacate Hass | E28: 1 | F28: 700 | G28: Junio | I28: GALAGRO SUROESTE ANT. | J28: Mónica Lucero Valencia Montoya
I29: GALAGRO SUROESTE ANT. | J29: John Álvaro Correa Castaño
I30: GALAGRO URABA ANT. | J30: Stefanía Builes Rodríguez
I31: GALAGRO URABA ANT. | J31: (Vacante) José Eliécer Borja David
I32: GALAGRO VALLE DE ABURRA ANT. | J32: Katherine Bedoya Rodas
I33: GALAGRO VALLE DE ABURRA ANT. | J33: Estefania Osorio Usuga

Sheet Act Campo
A1: ID | B1: Estado | C1: Asunto | D1: ID de cliente | E1: Cliente | F1: Tipo de visita | G1: Propietario | H1: LinkUbicacion | I1: Dirección | J1: Estado1 | K1: Creado el | L1: Fecha/Hora de inicio | M1: Fecha/Hora de fin | N1: Fecha/Hora Inic.visita | O1: Fecha/Hora Fin visita | P1: Notas | Q1: Territorio de ventas | R1: Organización de ventas | S1: Creados por | T1: Ubicación | U1: Observaciones Visita | V1: Cultivo | W1: Recomendaciones | X1: Estado cultivo | Y1: Hectáreas | Z1: Oportunidades comerciales | AA1: Estado2 | AB1: zaUbicacion | AC1: Est.Fed./Prov. | AD1: Ciudad | AE1: Link Ubicacion | AF1: mes | AH1: Cuenta de ID de cliente
A2: 194527 | B2: Completado | C2: Promoción portafolio | D2: 1466019 | E2: CEBALLOS ORTIZ JORGE LEONARDO | F2: Evento Especial | G2: Angie Cristina Rodríguez Muñoz | I2: CR 4 B CS 3 URB IMPERIO REAL / 5483 NARIÑO / CO | J2: NARIÑO | K2: 46141.759 | L2: 46144.333 | M2: 46144.625 | N2: 46144.375 | O2: 46144.584 | Q2: GALAGRO NARIÑO NAL. | R2: GALAGRO | S2: Angie Cristina Rodríguez Muñoz | T2: CEBALLOS ORTIZ JORGE LEONARDO / CR 4 B CS 3 URB IMPERIO REAL / 5483 NARIÑO / CO | Y2: 0 | AB2: CR 4 B CS 3 URB IMPERIO REAL / 5483 NARIÑO | AC2: NARIÑO | AD2: NARIÑO | AF2: =TEXT(L2,"mmmm") -> mayo | AH2: Territorio de ventas | AI2: mes | AJ2: Propietario | AK2: Tipo de visita | AL2: Total
A3: 194663 | B3: Completado | C3: Charla tecnica | D3: 1590115 | E3: JACINTO ROJAS ASOPRODUJEN | F3: Evento Especial | G3: Julio Andrés Cuspoca Martínez | I3: VEREDA PAECES BAJO / CO | J3: BOYACA | K3: 46146.234 | L3: 46146.375 | M3: 46146.708 | N3: 46146.384 | O3: 46146.716 | Q3: GALAGRO BOYACA NAL. | R3: GALAGRO | S3: Julio Andrés Cuspoca Martínez | T3: JACINTO ROJAS ASOPRODUJEN / VEREDA PAECES BAJO / CO | Y3: 0 | AB3: VEREDA PAECES BAJO | AC3: BOYACA | AF3: =TEXT(L3,"mmmm") -> mayo | AH3: PYC AGRÍCOLA ANT CÓRDOBA | AI3: febrero | AJ3: (Vacante) Jonathan De Jesús Salcedo Arango | AK3: Día de campo | AL3: 1
