Workbook

Sheet Tabla dinam gestion comercial
A1: Territorio | B1: Empleado | C1: Meta Cobertura Cliente | D1: Clientes Visitados | E1: Cobertura Clientes | F1: Meta Cobertura Cliente Final | G1: Cliente Final Visitados | H1: Cobertura Cliente Final | I1: Meta clientes nuevos | J1: Clientes Nuevos | K1: Cobertura Cliente Potencial | L1: Mes | M1: Meta Cobertura Cliente Final2 | O1: Comercial | P1: Territorio | Q1: Cargo | R1: Empresa | S1: Meta Parcelas | T1: Meta Actividades | U1: META | V1: Meta hectareas | W1: cultivos
A2: GALAGRO BOYACA NAL. | B2: Fredy Alberto Guzmán Daza | C2: 199 | D2: 20 | E2: 0.036764706 | G2: 39 | H2: 0.048611111 | I2: 120 | L2: Enero | M2: 60 | O2: Juana Andrea Moncaleano Sandoval | P2: GALAGRO NACIONAL DIRECCIÓN | Q2: DIR GALAGRO NACIONAL | R2: GALAGRO | S2: =SUM(S3:S18) -> 11 | T2: =SUM(T3:T18) -> 66 | U2: =T2+S2 -> 77 | V2: =SUM(V3:V18) -> 660 | W2: =SUM(W3:W18) -> 66 | X2: Excelente | Y2: >=90%
A3: GALAGRO BOYACA NAL. | B3: Julio Andrés Cuspoca Martínez | C3: 179 | D3: 16 | E3: 0.029411765 | G3: 29 | H3: 0.034722222 | I3: 120 | L3: Enero | M3: 60 | O3: Juana Andrea Moncaleano Sandoval | P3: GALAGRO CUNDINAMARCA NAL. | Q3: DIR GALAGRO NACIONAL | R3: GALAGRO | S3: 0.5 | T3: 3 | U3: =T3+S3 -> 3.5 | V3: 30 | W3: 3 | X3: Destacado | Y3: 75%<>90%
A4: GALAGRO CAUCA NAL. | B4: (Vacante) Edwin Francisco Fernandez Molina | C4: 91 | I4: 120 | L4: Enero | M4: 60 | O4: Juana Andrea Moncaleano Sandoval | P4: GALAGRO NACIONAL FLORES | Q4: DIR GALAGRO NACIONAL | R4: GALAGRO | S4: 0.5 | T4: 3 | U4: =T4+S4 -> 3.5 | V4: 30 | W4: 3 | X4: En desarrollo | Y4: <74%
A5: GALAGRO CUNDINAMARCA NAL. | B5: Jorge Eduardo López Vargas | C5: 182 | D5: 34 | E5: 0.18681319 | G5: 69 | H5: 0.10138889 | I5: 120 | L5: Enero | M5: 60 | O5: Juana Andrea Moncaleano Sandoval | P5: GALAGRO SANTANDER NAL. | Q5: DIR GALAGRO NACIONAL | R5: GALAGRO | S5: 0.5 | T5: 3 | U5: =T5+S5 -> 3.5 | V5: 30 | W5: 3 | X5: Crítico | Y5: <60%
A6: GALAGRO EJE CAFETERO Y VALLE NORTE NAL. | B6: (Vacante) María Camila López López | C6: 98 | I6: 120 | L6: Enero | M6: 60 | O6: Juana Andrea Moncaleano Sandoval | P6: GALAGRO TOLIMA NAL. | Q6: DIR GALAGRO NACIONAL | R6: GALAGRO | S6: 0.5 | T6: 3 | U6: =T6+S6 -> 3.5 | V6: 30 | W6: 3
A7: GALAGRO EJE CAFETERO Y VALLE NORTE NAL. | B7: César Augusto Escarria Reyes | C7: 24 | D7: 15 | E7: 0.15306122 | G7: 51 | H7: 0.066666667 | I7: 120 | L7: Enero | M7: 60 | O7: Juana Andrea Moncaleano Sandoval | P7: GALAGRO VALLE CENTRO NAL. | Q7: DIR GALAGRO NACIONAL | R7: GALAGRO | S7: 0.5 | T7: 3 | U7: =T7+S7 -> 3.5 | V7: 30 | W7: 3
A8: GALAGRO EJE CAFETERO Y VALLE NORTE NAL. | B8: Sebastián Zapata Gutiérrez | C8: 43 | D8: 11 | E8: 0.1122449 | G8: 24 | H8: 0.033333333 | I8: 120 | L8: Enero | M8: 60 | O8: Fredy Alberto Guzmán Daza | P8: GALAGRO BOYACA NAL. | Q8: PROMOTOR GALAGRO NAL BOYACA | R8: GALAGRO | S8: 1 | T8: 6 | U8: =T8+S8 -> 7 | V8: 60 | W8: 6
A9: GALAGRO HUILA NAL. | B9: (Vacante) Jessica Nathalia Holguín Leal | C9: 257 | I9: 120 | L9: Enero | M9: 60 | O9: Julio Andrés Cuspoca Martínez | P9: GALAGRO BOYACA NAL. | Q9: PROMOTOR GALAGRO NAL BOYACA 2 | R9: GALAGRO | S9: 1 | T9: 6 | U9: =T9+S9 -> 7 | V9: 60 | W9: 6
A10: GALAGRO NARIÑO NAL. | B10: Angie Cristina Rodríguez Muñoz | C10: 51 | D10: 9 | E10: 0.059602649 | G10: 15 | H10: 0.016666667 | I10: 120 | L10: Enero | M10: 60 | O10: (Vacante) María Camila López López | P10: GALAGRO EJE CAFETERO Y VALLE NORTE NAL. | Q10: PROMOTOR GALAGRO NAL CALDAS | R10: GALAGRO | S10: 0.5 | T10: 3 | U10: =T10+S10 -> 3.5 | V10: 30 | W10: 3
A11: GALAGRO NARIÑO NAL. | B11: Juan José Lagos Regalado | C11: 52 | D11: 22 | E11: 0.14569536 | G11: 46 | H11: 0.063888889 | I11: 120 | L11: Enero | M11: 60 | O11: (Vacante) Edwin Francisco Fernandez Molina | P11: GALAGRO CAUCA NAL. | Q11: PROMOTOR GALAGRO NAL CAUCA | R11: GALAGRO | S11: 0.5 | T11: 3 | U11: =T11+S11 -> 3.5 | V11: 30 | W11: 3
A12: GALAGRO NORTE DE SANTANDER NAL. | B12: Vladimir Leonardo Rondón Basto | C12: 152 | D12: 23 | E12: 0.15131579 | G12: 34 | H12: 0.047222222 | I12: 120 | L12: Enero | M12: 60 | O12: (Vacante) Jessica Nathalia Holguín Leal | P12: GALAGRO HUILA NAL. | Q12: PROMOTOR GALAGRO NAL HUILA | R12: GALAGRO | S12: 0.5 | T12: 3 | U12: =T12+S12 -> 3.5 | V12: 30 | W12: 3
A13: GALAGRO SANTANDER NAL. | B13: Annuar Andrey Hoyos Muñoz | C13: 194 | D13: 9 | E13: 0.046391753 | G13: 26 | H13: 0.036111111 | I13: 120 | L13: Enero | M13: 60 | O13: Angie Cristina Rodríguez Muñoz | P13: GALAGRO NARIÑO NAL. | Q13: PROMOTOR GALAGRO NAL NARIÑO 2 | R13: GALAGRO | S13: 1 | T13: 6 | U13: =T13+S13 -> 7 | V13: 60 | W13: 6
A14: GALAGRO BOYACA NAL. | B14: Fredy Alberto Guzmán Daza | C14: 199 | D14: 53 | E14: 0.097426471 | G14: 79 | H14: 0.10972222 | I14: 120 | L14: Febrero | M14: 60 | O14: Juan José Lagos Regalado | P14: GALAGRO NARIÑO NAL. | Q14: PROMOTOR GALAGRO NAL NARIÑO 3 | R14: GALAGRO | S14: 1 | T14: 6 | U14: =T14+S14 -> 7 | V14: 60 | W14: 6
A15: GALAGRO BOYACA NAL. | B15: Julio Andrés Cuspoca Martínez | C15: 179 | D15: 33 | E15: 0.060661765 | G15: 74 | H15: 0.0875 | I15: 120 | L15: Febrero | M15: 60 | O15: Vladimir Leonardo Rondón Basto | P15: GALAGRO NORTE DE SANTANDER NAL. | Q15: PROMOTOR GALAGRO NAL NORTE SANTANDER 2 | R15: GALAGRO | S15: 0.5 | T15: 3 | U15: =T15+S15 -> 3.5 | V15: 30 | W15: 3
A16: GALAGRO CAUCA NAL. | B16: (Vacante) Edwin Francisco Fernandez Molina | C16: 91 | I16: 120 | L16: Febrero | M16: 60 | O16: César Augusto Escarria Reyes | P16: GALAGRO EJE CAFETERO Y VALLE NORTE NAL. | Q16: PROMOTOR GALAGRO NAL QUINDIO | R16: GALAGRO | S16: 1 | T16: 6 | U16: =T16+S16 -> 7 | V16: 60 | W16: 6
A17: GALAGRO CUNDINAMARCA NAL. | B17: Jorge Eduardo López Vargas | C17: 182 | D17: 32 | E17: 0.17582418 | G17: 68 | H17: 0.10416667 | I17: 120 | L17: Febrero | M17: 60 | O17: Sebastián Zapata Gutiérrez | P17: GALAGRO EJE CAFETERO Y VALLE NORTE NAL. | Q17: PROMOTOR GALAGRO NAL RISARALDA | R17: GALAGRO | S17: 1 | T17: 6 | U17: =T17+S17 -> 7 | V17: 60 | W17: 6
A18: GALAGRO EJE CAFETERO Y VALLE NORTE NAL. | B18: (Vacante) María Camila López López | C18: 98 | I18: 120 | L18: Febrero | M18: 60 | O18: Annuar Andrey Hoyos Muñoz | P18: GALAGRO SANTANDER NAL. | Q18: PROMOTOR GALAGRO NAL SANTANDER | R18: GALAGRO | S18: 0.5 | T18: 3 | U18: =T18+S18 -> 3.5 | V18: 30 | W18: 3
A19: GALAGRO EJE CAFETERO Y VALLE NORTE NAL. | B19: César Augusto Escarria Reyes | C19: 24 | D19: 13 | E19: 0.13265306 | G19: 32 | H19: 0.038888889 | I19: 120 | L19: Febrero | M19: 60 | O19: Jorge Eduardo López Vargas | P19: GALAGRO CUNDINAMARCA NAL. | Q19: PROMOTOR GALAGRO NAL CUNDINAMARCA | R19: GALAGRO | S19: 0.5 | T19: 3 | U19: =T19+S19 -> 3.5 | V19: 30 | W19: 3
A20: GALAGRO EJE CAFETERO Y VALLE NORTE NAL. | B20: Sebastián Zapata Gutiérrez | C20: 43 | D20: 13 | E20: 0.13265306 | G20: 32 | H20: 0.044444444 | I20: 120 | L20: Febrero | M20: 60
A21: GALAGRO HUILA NAL. | B21: (Vacante) Jessica Nathalia Holguín Leal | C21: 257 | I21: 120 | L21: Febrero | M21: 60
A22: GALAGRO NARIÑO NAL. | B22: Angie Cristina Rodríguez Muñoz | C22: 51 | D22: 11 | E22: 0.072847682 | G22: 28 | H22: 0.031944444 | I22: 120 | L22: Febrero | M22: 60
A23: GALAGRO NARIÑO NAL. | B23: Juan José Lagos Regalado | C23: 52 | D23: 19 | E23: 0.12582781 | G23: 61 | H23: 0.084722222 | I23: 120 | L23: Febrero | M23: 60
A24: GALAGRO NORTE DE SANTANDER NAL. | B24: Vladimir Leonardo Rondón Basto | C24: 152 | D24: 22 | E24: 0.14473684 | G24: 50 | H24: 0.069444444 | I24: 120 | L24: Febrero | M24: 60
A25: GALAGRO SANTANDER NAL. | B25: Annuar Andrey Hoyos Muñoz | C25: 194 | D25: 13 | E25: 0.067010309 | G25: 35 | H25: 0.048611111 | I25: 120 | L25: Febrero | M25: 60
A26: GALAGRO BOYACA NAL. | B26: Fredy Alberto Guzmán Daza | C26: 199 | D26: 46 | E26: 0.084558824 | G26: 70 | H26: 0.1 | I26: 120 | L26: Marzo | M26: 60
A27: GALAGRO BOYACA NAL. | B27: Julio Andrés Cuspoca Martínez | C27: 179 | D27: 32 | E27: 0.058823529 | G27: 73 | H27: 0.079166667 | I27: 120 | L27: Marzo | M27: 60
A28: GALAGRO CAUCA NAL. | B28: (Vacante) Edwin Francisco Fernandez Molina | C28: 91 | I28: 120 | L28: Marzo | M28: 60
A29: GALAGRO CUNDINAMARCA NAL. | B29: Jorge Eduardo López Vargas | C29: 182 | D29: 27 | E29: 0.14835165 | G29: 57 | H29: 0.086111111 | I29: 120 | L29: Marzo | M29: 60
A30: GALAGRO EJE CAFETERO Y VALLE NORTE NAL. | B30: (Vacante) María Camila López López | C30: 98 | I30: 120 | L30: Marzo | M30: 60
A31: GALAGRO EJE CAFETERO Y VALLE NORTE NAL. | B31: César Augusto Escarria Reyes | C31: 24 | D31: 15 | E31: 0.15306122 | G31: 48 | H31: 0.061111111 | I31: 120 | L31: Marzo | M31: 60
A32: GALAGRO EJE CAFETERO Y VALLE NORTE NAL. | B32: Sebastián Zapata Gutiérrez | C32: 43 | D32: 7 | E32: 0.071428571 | G32: 7 | H32: 0.0097222222 | I32: 120 | L32: Marzo | M32: 60
A33: GALAGRO HUILA NAL. | B33: (Vacante) Jessica Nathalia Holguín Leal | C33: 257 | I33: 120 | L33: Marzo | M33: 60
A34: GALAGRO NARIÑO NAL. | B34: Angie Cristina Rodríguez Muñoz | C34: 51 | D34: 11 | E34: 0.072847682 | G34: 27 | H34: 0.029166667 | I34: 120 | L34: Marzo | M34: 60
A35: GALAGRO NARIÑO NAL. | B35: Juan José Lagos Regalado | C35: 52 | D35: 22 | E35: 0.14569536 | G35: 51 | H35: 0.070833333 | I35: 120 | L35: Marzo | M35: 60
A36: GALAGRO NORTE DE SANTANDER NAL. | B36: Vladimir Leonardo Rondón Basto | C36: 152 | D36: 20 | E36: 0.13157895 | G36: 42 | H36: 0.058333333 | I36: 120 | L36: Marzo | M36: 60
A37: GALAGRO SANTANDER NAL. | B37: Annuar Andrey Hoyos Muñoz | C37: 194 | D37: 18 | E37: 0.092783505 | G37: 55 | H37: 0.076388889 | I37: 120 | L37: Marzo | M37: 60
N62: Meta Clientes Nuevos | O62: Cant. Clientes Nuevos | P62: Ejecución Clientes Nuevos
N63: 120
N64: 120
...

Sheet mensual
A1: #VALUE! | C1: Reporte de desempeño comercial - Individual
C2: Reporte de desempeño comercial | H2: Nombre: | J2: Vladimir Leonardo Rondón Basto
C3: Resumen trimestral | H3: Cargo: | J3: =VLOOKUP(J2,'Tabla dinam gestion comercial'!O:Q,3,0) -> PROMOTOR GALAGRO NAL NORTE SANTANDER 2
C4: Trimestre 1 | H4: Territorio: | J4: =VLOOKUP(J2,'Tabla dinam gestion comercial'!O:P,2,0) -> GALAGRO NORTE DE SANTANDER NAL.
C5: Enero-marzo de 2026 | H5: Empresa: | J5: =VLOOKUP(J2,'Tabla dinam gestion comercial'!O:R,4,0) -> GALAGRO
A7: Resultado global
A8: =SUMPRODUCT($D$15:$D$26, $F$15:$F$26) -> 0.22080083
M9: Valor | N9: =A8*100 -> 22.080083 | O9: =ROUND(N9,0)&"%" -> 22%
M10: Restante | N10: =100-N9 -> 77.919917
M11: Oculto | N11: 100
A12: =IF(A8>=90%,"Excelente",IF(A8>=75%,"Destacado",IF(A8>=59%,"En desarrollo","Crítico"))) -> Crítico
A13: Indicadores clave
A14: Indicador | D14: Resultado trimestre | E14: Meta | F14: Peso | G14: Gestión enero | H14: Gestión febrero | I14: Gestión marzo | J14: Meta esperada prom. mes | K14: Criterios de medición
A15: #VALUE! | B15: Ejecución visitas Cliente Final | C15: =IF(D15>=90%,"⬤",IF(D15>=75%,"⬤",IF(D15>=60%,"⬤","⬤"))) -> ⬤ | D15: =IFERROR(MIN(100%,SUM(G15:I15)/($J15*3)),0) -> 0.7 | E15: 0.9 | F15: 0.1 | G15: =SUMIFS( 'Tabla dinam gestion comercial'!$G:$G, 'Tabla dinam gestion comercial'!$B:$B,$J$2, 'Tabla dinam gestion comercial'!$L:$L,"Enero" ) -> 34 | H15: =SUMIFS( 'Tabla dinam gestion comercial'!$G:$G, 'Tabla dinam gestion comercial'!$B:$B,$J$2, 'Tabla dinam gestion comercial'!$L:$L,"Febrero" ) -> 50 | I15: =SUMIFS( 'Tabla dinam gestion comercial'!$G:$G, 'Tabla dinam gestion comercial'!$B:$B,$J$2, 'Tabla dinam gestion comercial'!$L:$L,"Marzo" ) -> 42 | J15: {=IFERROR((SUM(_xlfn.UNIQUE(_xlfn._xlws.FILTER('Tabla dinam gestion comercial'!$M:$M,('Tabla dinam gestion comercial'!$B:$B=$J$2)*('Tabla dinam gestion comercial'!$L:$L="Enero"))))+SUM(_xlfn.UNIQUE(_xlfn._xlws.FILTER('Tabla dinam gestion comercial'!$M:$M,('Tabla dinam gestion comercial'!$B:$B=$J$2)*('Tabla dinam gestion comercial'!$L:$L="Febrero"))))+SUM(_xlfn.UNIQUE(_xlfn._xlws.FILTER('Tabla dinam gestion comercial'!$M:$M,('Tabla dinam gestion comercial'!$B:$B=$J$2)*('Tabla dinam gestion comercial'!$L:$L="Marzo")))))/3,0)} -> 60 | K15: Mide el cumplimiento acumulado de visitas del período. Se suman las visitas realizadas en los tres meses y se comparan contra la meta mensual multiplicada por el número de meses evaluados.
A16: #VALUE! | B16: Cobertura clientes | C16: =IF(D16>=90%,"⬤",IF(D16>=75%,"⬤",IF(D16>=60%,"⬤","⬤"))) -> ⬤ | D16: =IFERROR(MIN(100%,SUM(G16:I16)/($J16*3)),0) -> 0.42763158 | E16: 0.9 | F16: 0.1 | G16: =SUMIFS('Tabla dinam gestion comercial'!$D:$D,'Tabla dinam gestion comercial'!$B:$B,$J$2,'Tabla dinam gestion comercial'!$L:$L,"Enero") -> 23 | H16: =SUMIFS('Tabla dinam gestion comercial'!$D:$D,'Tabla dinam gestion comercial'!$B:$B,$J$2,'Tabla dinam gestion comercial'!$L:$L,"Febrero") -> 22 | I16: =SUMIFS('Tabla dinam gestion comercial'!$D:$D,'Tabla dinam gestion comercial'!$B:$B,$J$2,'Tabla dinam gestion comercial'!$L:$L,"Marzo") -> 20 | J16: =IFERROR(SUMIFS('Tabla dinam gestion comercial'!$C$2:$C$62,'Tabla dinam gestion comercial'!$B$2:$B$62,$J$2)/3,0)/3 -> 50.666667 | K16: Mide cuántos clientes del territorio fueron visitados frente a la meta mensual asignada. Se calcula con el promedio de clientes visitados durante los meses evaluados y se compara contra la meta de cobertura. La meta no se acumula entre meses. Si el resultado supera la meta, el cumplimiento máximo reconocido es del 100%.
A17: #VALUE! | B17: Clientes Nuevos | C17: =IF(D17>=90%,"⬤",IF(D17>=75%,"⬤",IF(D17>=60%,"⬤","⬤"))) -> ⬤ | D17: =IFERROR(AVERAGE(G17/J17,H17/J17,I17/J17),0) -> 0 | E17: 0.9 | F17: 0.1 | G17: =SUMIFS('Tabla dinam gestion comercial'!$J:$J,'Tabla dinam gestion comercial'!$B:$B,$J$2,'Tabla dinam gestion comercial'!$L:$L,"*Enero*") -> 0 | H17: =SUMIFS('Tabla dinam gestion comercial'!$J:$J,'Tabla dinam gestion comercial'!$B:$B,$J$2,'Tabla dinam gestion comercial'!$L:$L,"*Febrero*") -> 0 | I17: =SUMIFS('Tabla dinam gestion comercial'!$J:$J,'Tabla dinam gestion comercial'!$B:$B,$J$2,'Tabla dinam gestion comercial'!$L:$L,"*Marzo*") -> 0 | J17: =ROUNDUP(SUMIFS('Tabla dinam gestion comercial'!$I:$I,'Tabla dinam gestion comercial'!$B:$B,$J$2)/3,0)/12 -> 10 | K17: Cuenta clientes nuevos y recuperados que registran una gestión o una venta durante el período. El resultado toma el total acumulado alcanzado y lo compara contra la meta esperada.
A18: Indicador | D18: Resultado trimestre | E18: Meta | F18: Peso | G18: Gestión enero | H18: Gestión febrero | I18: Gestión marzo | J18: Meta acum. período | K18: Criterios de medición
A19: #VALUE! | B19: Recomendaciones | C19: =IF(D19>=90%,"⬤",IF(D19>=75%,"⬤",IF(D19>=60%,"⬤","⬤"))) -> ⬤ | D19: =IFERROR(MIN(150%,SUM(G19:I19)/J19),0) -> 0.0010121281 | E19: 0.9 | F19: 0.2 | G19: =SUMIFS(Tecnico!$D:$D,Tecnico!$A:$A,$J$4,Tecnico!$K:$K,"Enero") -> 0 | H19: =SUMIFS(Tecnico!$D:$D,Tecnico!$A:$A,$J$4,Tecnico!$K:$K,"Febrero") -> 0 | I19: =SUMIFS(Tecnico!$D:$D,Tecnico!$A:$A,$J$4,Tecnico!$K:$K,"Marzo") -> 442300 | J19: =SUMIFS(Tecnico!$C:$C,Tecnico!$A:$A,$J$4) -> 437000000 | K19: Suma las recomendaciones generadas durante el período evaluado y compara ese total contra la meta acumulada. El resultado muestra el porcentaje de cumplimiento alcanzado frente a la meta del trimestre.
A20: #VALUE! | B20: Referencias | C20: =IF(D20>=90%,"⬤",IF(D20>=75%,"⬤",IF(D20>=60%,"⬤","⬤"))) -> ⬤ | D20: =IFERROR(AVERAGE(G20:I20)/J20,0) -> 0.017241379 | E20: 0.9 | F20: 0.1 | G20: =SUMIFS(Tecnico!$J:$J,Tecnico!$A:$A,$J$4,Tecnico!$K:$K,"Enero") -> 0 | H20: =SUMIFS(Tecnico!$J:$J,Tecnico!$A:$A,$J$4,Tecnico!$K:$K,"Febrero") -> 0 | I20: =SUMIFS(Tecnico!$J:$J,Tecnico!$A:$A,$J$4,Tecnico!$K:$K,"Marzo") -> 3 | J20: =SUMIFS(Tecnico!$H:$H,Tecnico!$A:$A,$J$4)/3 -> 58 | K20: Mide el cumplimiento de referencias gestionadas frente a la meta esperada del período. Se suman las referencias generadas durante los meses evaluados y se comparan contra la meta mensual de SKU activas multiplicada por el número de meses.
A21: Indicador | D21: Resultado | E21: Meta | F21: Peso | G21: Gestión enero | H21: Gestión febrero | I21: Gestión marzo | J21: Meta acum. período | K21: Criterios de medición
A22: #VALUE! | B22: Leads calificados | C22: =IF(D22>=90%,"⬤",IF(D22>=75%,"⬤",IF(D22>=60%,"⬤","⬤"))) -> ⬤ | D22: =IFERROR(SUM(G22:I22)/J22,0%) -> 0 | E22: 0.9 | F22: 0.1 | G22: =IFERROR(SUMIFS(Leads!$D:$D,Leads!$C:$C,$J$2,Leads!$I:$I,"Enero"),0) -> 0 | H22: =IFERROR(SUMIFS(Leads!$D:$D,Leads!$C:$C,$J$2,Leads!$I:$I,"Febrero"),0) -> 0 | I22: =IFERROR(SUMIFS(Leads!$D:$D,Leads!$C:$C,$J$2,Leads!$I:$I,"Marzo"),0) -> 0 | J22: =MAX(1,IFERROR(SUMIFS(Leads!$D:$D,Leads!$C:$C,$J$2,Leads!$I:$I,"Enero"),0))+MAX(1,IFERROR(SUMIFS(Leads!$D:$D,Leads!$C:$C,$J$2,Leads!$I:$I,"Febrero"),0))+MAX(1,IFERROR(SUMIFS(Leads!$D:$D,Leads!$C:$C,$J$2,Leads!$I:$I,"Marzo"),0)) -> 3 | K22: Mide la generación de leads frente a la meta esperada. La meta considera mínimo 1 lead por mes evaluado y aumenta según los leads generados, con el fin de incentivar la creación constante de oportunidades comerciales. Si no se generan leads, el cumplimiento es 0%.
A23: #VALUE! | B23: Leads calificados a tiempo | C23: =IF(D23>=90%,"⬤",IF(D23>=75%,"⬤",IF(D23>=60%,"⬤","⬤"))) -> ⬤ | D23: =IFERROR(SUM(G23:I23)/J23,0%) -> 0 | E23: 0.9 | F23: 0.1 | G23: =IFERROR(SUMIFS(Leads!$E:$E,Leads!$C:$C,$J$2,Leads!$I:$I,"Enero"),0) -> 0 | H23: =IFERROR(SUMIFS(Leads!$E:$E,Leads!$C:$C,$J$2,Leads!$I:$I,"Febrero"),0) -> 0 | I23: =IFERROR(SUMIFS(Leads!$E:$E,Leads!$C:$C,$J$2,Leads!$I:$I,"Marzo"),0) -> 0 | J23: =MAX(1,IFERROR(SUMIFS(Leads!$D:$D,Leads!$C:$C,$J$2,Leads!$I:$I,"Enero"),0))+MAX(1,IFERROR(SUMIFS(Leads!$D:$D,Leads!$C:$C,$J$2,Leads!$I:$I,"Febrero"),0))+MAX(1,IFERROR(SUMIFS(Leads!$D:$D,Leads!$C:$C,$J$2,Leads!$I:$I,"Marzo"),0)) -> 3 | K23: Mide el porcentaje de leads que fueron calificados dentro del tiempo establecido (48 horas después de generado). Se compara la cantidad de leads calificados oportunamente frente al total de leads que debían ser gestionados en el período.
A24: #VALUE! | B24: Impacto en clientes (Actividades de campo) | C24: =IF(D24>=90%,"⬤",IF(D24>=75%,"⬤",IF(D24>=60%,"⬤","⬤"))) -> ⬤ | D24: =MIN(IFERROR(SUM(G24:I24)/J24,0%),150%) -> 0 | E24: 0.9 | F24: 0.1 | G24: =COUNTIFS('Act Campo'!$Q$2:$Q$997,$J$4,'Act Campo'!$AF$2:$AF$997,"Enero") -> 0 | H24: =COUNTIFS('Act Campo'!$Q$2:$Q$997,$J$4,'Act Campo'!$AF$2:$AF$997,"Febrero") -> 0 | I24: =COUNTIFS('Act Campo'!$Q$2:$Q$997,$J$4,'Act Campo'!$AF$2:$AF$997,"Marzo") -> 0 | J24: =IFERROR(VLOOKUP(J2,'Tabla dinam gestion comercial'!$O:$U,7,0),0) -> 3.5 | K24: Mide el cumplimiento de actividades y parcelas frente a la meta del territorio. Por cada promotor se esperan 3 actividades trimestrales y 0,5 parcelas, con reconocimiento máximo hasta el 150%.
A25: #VALUE! | B25: Hectáreas de cultivos impactados | C25: =IF(D25>=90%,"⬤",IF(D25>=75%,"⬤",IF(D25>=60%,"⬤","⬤"))) -> ⬤ | D25: =MIN(IFERROR(SUM(G25:I25)/J25,0%),150%) -> 0.62222222 | E25: 0.9 | F25: 0.05 | G25: =SUMIFS(Fincas!$F:$F,Fincas!$B:$B,$J$4,Fincas!$G:$G,"Enero") -> 1 | H25: =SUMIFS(Fincas!$F:$F,Fincas!$B:$B,$J$4,Fincas!$G:$G,"Febrero") -> 16 | I25: =SUMIFS(Fincas!$F:$F,Fincas!$B:$B,$J$4,Fincas!$G:$G,"Marzo") -> 39 | J25: =ROUNDUP(_xlfn.MAXIFS('Tabla dinam gestion comercial'!$V:$V,'Tabla dinam gestion comercial'!$O:$O,$J$2)*3,0) -> 90 | K25: Mide las hectáreas gestionadas en el período frente a la meta del territorio. Cada promotor debe gestionar 30 hectáreas mensuales, equivalentes a 90 por trimestre, con reconocimiento de cumplimiento máximo hasta el 150%.
A26: #VALUE! | B26: Cultivos impactados | C26: =IF(D26>=90%,"⬤",IF(D26>=75%,"⬤",IF(D26>=60%,"⬤","⬤"))) -> ⬤ | D26: =MIN(IFERROR(SUM(G26:I26)/J26,0%),150%) -> 1.5 | E26: 0.9 | F26: 0.05 | G26: =COUNTIFS(Fincas!$B:$B,$J$4,Fincas!$D:$D,"<>",Fincas!$G:$G,"Enero") -> 1 | H26: =COUNTIFS(Fincas!$B:$B,$J$4,Fincas!$D:$D,"<>",Fincas!$G:$G,"Febrero") -> 7 | I26: =COUNTIFS(Fincas!$B:$B,$J$4,Fincas!$D:$D,"<>",Fincas!$G:$G,"Marzo") -> 6 | J26: =ROUNDUP(SUMIFS('Tabla dinam gestion comercial'!$W:$W,'Tabla dinam gestion comercial'!$O:$O,$J$2),0) -> 3 | K26: Mide los cultivos gestionados en el período frente a la meta del territorio. Cada promotor debe gestionar mínimo 1 cultivo mensual, equivalente a 3 por trimestre, con reconocimiento de cumplimiento máximo hasta el 150%.
A27: #VALUE! | B27: Gestión de Cultivos Impactados | C27: =IF(D27>=90%,"⬤",IF(D27>=75%,"⬤",IF(D27>=60%,"⬤","⬤"))) -> ⬤ | D27: =(D25+D26)/2 -> 1.0611111 | E27: 0.9
A28: #VALUE! | B28: "Enfócate en las oportunidades de mejora y mantén el ritmo en tus fortalezas." ¡Tú puedes alcanzar tus objetivos! | G28: Requiere mejora (<60%) | H28: En desarrollo (60% - 74%) | J28: Bueno (>=75% - 89%) | K28: Excelente (>=90%)
A31: Oportunidades | D31: Fortalezas | H31: Resumen ejecutivo | K31: Plan de acción sugerido
A32: =IF($N$9>=90, "Para los perfeccionistas, siempre hay espacio de mejora. El siguiente reto es la sostenibilidad: analiza esos mínimos detalles o indicadores que rozaron la meta para blindar tu territorio contra cualquier imprevisto futuro. ¡La excelencia no se detiene!", IF($N$9>=75, "El camino a la cima está en los detalles. Para saltar al rango excelente, el foco debe estar en acelerar aquellos indicadores que se quedaron en amarillo o naranja. Ajustar la estrategia en estos puntos específicos liberará todo tu potencial comercial.", IF($N$9>=59, _xlfn._LONGTEXT("Aquí está tu mayor oportunidad de crecimiento. Al concentrar tus esfuerzos en levantar los indicadores que quedaron por debajo de la meta, verás un impacto inmediato en tu resultado global. Prioriza tus batallas, ajusta la planificación semanal y ve por e","sos puntos."), _xlfn._LONGTEXT("La meta está más cerca de lo que parece si nos enfocamos. El plan de acción inmediato exige concentrar la energía en revertir los indicadores críticos que están frenando tu avance. Define prioridades claras, solicita el apoyo necesario y da el primer paso",". ¡Cada mejora cuenta!")))) -> La meta está más cerca de lo que parece si nos enfocamos. El plan de acción inmediato exige concentrar la energía en revertir los indicadores críticos que están frenando tu avance. Define prioridades claras, solicita el apoyo necesario y da el primer paso. ¡Cada mejora cuenta! | D32: =IF($N$9>=90, _xlfn._LONGTEXT("Tus pilares de éxito están firmes. Destacas por una ejecución impecable en campo, un dominio absoluto de tus indicadores de mayor peso y una consistencia comercial admirable. Tu capacidad para superar las metas demuestra que tu estrategia en el territorio"," es sumamente efectiva."), IF($N$9>=75, "Cuentas con bases operativas y comerciales muy sólidas. Has demostrado un rendimiento sobresaliente en tus indicadores clave de gestión, logrando superar las metas esperadas en frentes cruciales. Esta efectividad es tu trampolín hacia el éxito absoluto.", IF($N$9>=59, "Aun en periodos retadores, tu esfuerzo ha dado frutos valiosos. Tienes indicadores específicos donde demuestras un gran compromiso y efectividad. Esas actividades en las que hoy brillas son el motor que debes usar para impulsar el resto de tu gestión.", _xlfn._LONGTEXT("Incluso en la dificultad, hay terreno ganado. Tu dedicación se hace visible en tus mejores indicadores del período. Esos pequeños o grandes logros demuestran que posees las habilidades necesarias; el objetivo ahora es replicar ese mismo esfuerzo en las de","más áreas.")))) -> Incluso en la dificultad, hay terreno ganado. Tu dedicación se hace visible en tus mejores indicadores del período. Esos pequeños o grandes logros demuestran que posees las habilidades necesarias; el objetivo ahora es replicar ese mismo esfuerzo en las demás áreas. | H32: =IF($N$9>=90, "¡Extraordinario desempeño! Este periodo refleja tu alto compromiso, disciplina y maestría en el territorio. Has alcanzado un nivel de excelencia que inspires al equipo. Mantén este ritmo ganador y sigue liderando con el ejemplo.", IF($N$9>=75, _xlfn._LONGTEXT("¡Gran trabajo en este periodo! Tu consistencia y esfuerzo te posicionan en un nivel destacado. Estás a muy pocos pasos de la excelencia total. El camino está trazado; con un pequeño empuje en los indicadores clave, el próximo trimestre pintarás el tablero"," completamente de verde."), IF($N$9>=59, _xlfn._LONGTEXT("Cerramos un trimestre de mucho aprendizaje y esfuerzo. Estás en pleno proceso de consolidación de tus objetivos. El potencial para crecer está ahí; este resultado es el punto de partida perfecto para enfocar la energía en las actividades que moverán la ag","uja hacia el siguiente nivel."), _xlfn._LONGTEXT("Este trimestre nos plantea un reto importante, pero también una gran oportunidad de reinvención. Cada desafío superado nos hace más fuertes. Es momento de revisar la estrategia, apoyarte en tus fortalezas y accionar un plan de mejora enfocado. ¡Tienes la ","capacidad para revertir este indicador y alcanzar tus metas!")))) -> Este trimestre nos plantea un reto importante, pero también una gran oportunidad de reinvención. Cada desafío superado nos hace más fuertes. Es momento de revisar la estrategia, apoyarte en tus fortalezas y accionar un plan de mejora enfocado. ¡Tienes la capacidad para revertir este indicador y alcanzar tus metas! | K32: =IF($N$9>=90,"Mantener el desempeño y asegurar la sostenibilidad de los resultados. Revisa los indicadores cercanos al límite, documenta las buenas prácticas y replica el modelo de gestión en el territorio.",IF($N$9>=75,"Priorizar los indicadores que quedaron por debajo del nivel excelente. Define acciones puntuales, responsables y fechas de seguimiento para llevar el resultado al siguiente rango.",IF($N$9>=59,"Enfocar el plan de trabajo en los indicadores con menor cumplimiento. Ajusta la planificación semanal, refuerza el seguimiento y concentra los esfuerzos en las actividades de mayor impacto.", "Activar un plan de mejora inmediato sobre los indicadores críticos. Define prioridades, solicita acompañamiento y realiza seguimiento semanal para recuperar el cumplimiento del territorio."))) -> Activar un plan de mejora inmediato sobre los indicadores críticos. Define prioridades, solicita acompañamiento y realiza seguimiento semanal para recuperar el cumplimiento del territorio.

Sheet X territorio
A1: #VALUE! | D1: Reporte de desempeño comercial - Territorio
D2: Reporte de desempeño comercial | G2: Nombre | H2: Estefania Osorio Usuga
D3: Resumen trimestral | G3: Cargo: | H3: =VLOOKUP(H2,'Tabla dinam gestion comercial'!O:Q,3,0) -> #N/A
D4: Primer trimestre | G4: Territorio: | H4: =VLOOKUP(H2,'Tabla dinam gestion comercial'!O:P,2,0) -> #N/A
D5: Enero-marzo de 2026 | G5: Empresa: | H5: =VLOOKUP(H2,'Tabla dinam gestion comercial'!O:R,4,0) -> #N/A
A6: Resultado global
A7: =SUMPRODUCT($D$14:$D$25, $F$14:$F$25) -> #DIV/0!
K8: Valor | L8: =A7*100 -> #DIV/0! | M8: =ROUND(L8,0)&"%" -> #DIV/0!
K9: Restante | L9: =100-L8 -> #DIV/0!
K10: Oculto | L10: 100
A11: =IF(A7>=90%,"Excelente",IF(A7>=75%,"Destacado",IF(A7>=59%,"En desarrollo","Crítico"))) -> #DIV/0!
A12: INDICADORES CLAVE
A13: Indicador | D13: Cumplimiento | E13: Meta | F13: Peso | G13: Gestión real x 3 meses | H13: Meta esperada x 3 meses | I13: Criterios de medición
A14: #VALUE! | B14: Ejecución visitas | C14: =IF(D14>=90%,"⬤",IF(D14>=75%,"⬤",IF(D14>=60%,"⬤","⬤"))) -> #DIV/0! | D14: =MIN(100%,G14/H14) -> #DIV/0! | E14: 0.9 | F14: 0.1 | G14: =SUMIFS('Tabla dinam gestion comercial'!$F:$F,'Tabla dinam gestion comercial'!$A:$A,$H$4) -> 0 | H14: =SUMIFS('Tabla dinam gestion comercial'!$M:$M,'Tabla dinam gestion comercial'!$A:$A,$H$4,'Tabla dinam gestion comercial'!$L:$L,"Enero")+SUMIFS('Tabla dinam gestion comercial'!$M:$M,'Tabla dinam gestion comercial'!$A:$A,$H$4,'Tabla dinam gestion comercial'!$L:$L,"Febrero")+SUMIFS('Tabla dinam gestion comercial'!$M:$M,'Tabla dinam gestion comercial'!$A:$A,$H$4,'Tabla dinam gestion comercial'!$L:$L,"Marzo") -> 0 | I14: Compara el total de visitas realizadas por los integrantes del territorio frente a la meta acumulada esperada. Cumplir o superar la meta equivale al 100%, y el resultado refleja el cumplimiento global del territorio en los meses evaluados.
A15: #VALUE! | B15: Cobertura clientes | C15: =IF(D15>=90%,"⬤",IF(D15>=75%,"⬤",IF(D15>=60%,"⬤","⬤"))) -> ⬤ | D15: =IFERROR(MIN(100%,G15/H15),0) -> 0 | E15: 0.9 | F15: 0.1 | G15: =SUMIFS('Tabla dinam gestion comercial'!$D:$D,'Tabla dinam gestion comercial'!$A:$A,$H$4,'Tabla dinam gestion comercial'!$L:$L,"Enero")+SUMIFS('Tabla dinam gestion comercial'!$D:$D,'Tabla dinam gestion comercial'!$A:$A,$H$4,'Tabla dinam gestion comercial'!$L:$L,"Febrero")+SUMIFS('Tabla dinam gestion comercial'!$D:$D,'Tabla dinam gestion comercial'!$A:$A,$H$4,'Tabla dinam gestion comercial'!$L:$L,"Marzo") -> 0 | H15: =(SUMIFS('Tabla dinam gestion comercial'!$C:$C,'Tabla dinam gestion comercial'!$A:$A,$H$4,'Tabla dinam gestion comercial'!$L:$L,"Enero")+SUMIFS('Tabla dinam gestion comercial'!$C:$C,'Tabla dinam gestion comercial'!$A:$A,$H$4,'Tabla dinam gestion comercial'!$L:$L,"Febrero")+SUMIFS('Tabla dinam gestion comercial'!$C:$C,'Tabla dinam gestion comercial'!$A:$A,$H$4,'Tabla dinam gestion comercial'!$L:$L,"Marzo"))/3 -> 0 | I15: Mide la cobertura promedio mensual de clientes visitados por el territorio frente a la meta asignada. Se suman los clientes visitados por los integrantes del equipo en cada mes y luego se calcula el promedio del período evaluado. La meta de cobertura es mensual y no se acumula entre meses.
A16: #VALUE! | B16: Nuevos clientes | C16: =IF(D16>=90%,"⬤",IF(D16>=75%,"⬤",IF(D16>=60%,"⬤","⬤"))) -> #DIV/0! | D16: =G16/H16 -> #DIV/0! | E16: 0.9 | F16: 0.1 | G16: =SUMIFS('Tabla dinam gestion comercial'!$I:$I,'Tabla dinam gestion comercial'!$A:$A,$H$4,'Tabla dinam gestion comercial'!$L:$L,"Marzo") -> 0 | H16: =ROUNDUP((SUMIFS('Tabla dinam gestion comercial'!$H:$H,'Tabla dinam gestion comercial'!$A:$A,$H$4,'Tabla dinam gestion comercial'!$L:$L,"Enero")+SUMIFS('Tabla dinam gestion comercial'!$H:$H,'Tabla dinam gestion comercial'!$A:$A,$H$4,'Tabla dinam gestion comercial'!$L:$L,"Febrero")+SUMIFS('Tabla dinam gestion comercial'!$H:$H,'Tabla dinam gestion comercial'!$A:$A,$H$4,'Tabla dinam gestion comercial'!$L:$L,"Marzo"))/12,0) -> 0 | I16: Mide los clientes nuevos y recuperados del territorio que registran gestión o venta. La meta se calcula de forma proporcional al período evaluado, tomando la meta anual dividida entre 12 meses.
A17: Indicador | D17: Cumplimiento | E17: Meta | F17: Peso | G17: Gestión real | H17: Meta acum. período | I17: Criterios de medición
A18: #VALUE! | B18: Recomendados | C18: =IF(D18>=90%,"⬤",IF(D18>=75%,"⬤",IF(D18>=60%,"⬤","⬤"))) -> ⬤ | D18: =IFERROR((G18/H18),"0") -> 0 | E18: 0.9 | F18: 0.2 | G18: =SUMIFS(Tecnico!$D:$D,Tecnico!$A:$A,$H$4) -> 0 | H18: =SUMIFS(Tecnico!$C:$C,Tecnico!$A:$A,$H$4) -> 0 | I18: Suma las recomendaciones generadas en el trimestre, y compara ese total contra la meta acumulada del período. El resultado muestra qué porcentaje de la meta trimestral se alcanzó.
A19: #VALUE! | B19: Referencias | C19: =IF(D19>=90%,"⬤",IF(D19>=75%,"⬤",IF(D19>=60%,"⬤","⬤"))) -> ⬤ | D19: =IF(AND(G19=0, H19=0), 100%, IF(G19=0, 0%, G19/H19)) -> 1 | E19: 0.9 | F19: 0.1 | G19: =SUMIFS(Tecnico!$J:$J,Tecnico!$A:$A,$H$4) -> 0 | H19: =SUMIFS(Tecnico!$H:$H,Tecnico!$A:$A,$H$4)/3 -> 0 | I19: Mide cuántas referencias se gestionaron frente a la meta esperada. Se suman las referencias del trimestre, y se comparan contra la meta promedio.
A20: Indicador | D20: Cumplimiento | E20: Meta | F20: Peso | G20: Gestión real | H20: Meta acum. período | I20: Criterios de medición
A21: #VALUE! | B21: Leads calificados | C21: =IF(D21>=90%,"⬤",IF(D21>=75%,"⬤",IF(D21>=60%,"⬤","⬤"))) -> ⬤ | D21: =IF(H21=0,0,IFERROR(G21/H21,0)) -> 0 | E21: 0.9 | F21: 0.1 | G21: =SUMIFS(Leads!$P:$P,Leads!$L:$L,$H$4) -> 0 | H21: {=IFERROR(COUNTA(_xlfn.UNIQUE(_xlfn._xlws.FILTER('Tabla dinam gestion comercial'!$O:$O,(TRIM('Tabla dinam gestion comercial'!$P:$P)=TRIM($H$4))*('Tabla dinam gestion comercial'!$O:$O<>""))))*3,0)} -> 3 | I21: Mide los leads calificados del territorio durante el período evaluado frente a la meta esperada. La meta se calcula según la cantidad de comerciales del territorio y los meses evaluados, permitiendo reflejar tanto la generación como la gestión efectiva de los leads.
A22: #VALUE! | B22: Leads calificados a tiempo | C22: =IF(D22>=90%,"⬤",IF(D22>=75%,"⬤",IF(D22>=60%,"⬤","⬤"))) -> ⬤ | D22: =IF(H22=0,0,IFERROR(G22/H22,0)) -> 0 | E22: 0.9 | F22: 0.1 | G22: =SUMIFS(Leads!$P:$P,Leads!$L:$L,$H$4) -> 0 | H22: {=IFERROR(COUNTA(_xlfn.UNIQUE(_xlfn._xlws.FILTER('Tabla dinam gestion comercial'!$O:$O,(TRIM('Tabla dinam gestion comercial'!$P:$P)=TRIM($H$4))*('Tabla dinam gestion comercial'!$O:$O<>""))))*3,0)} -> 3 | I22: Mide los leads calificados a tiempo frente a la meta esperada del período. La meta se calcula según la cantidad de comerciales del territorio y los meses evaluados, permitiendo reflejar tanto la generación esperada como la oportunidad en la gestión.
A23: #VALUE! | B23: Impacto en clientes (actividades de campo) | C23: =IF(D23>=90%,"⬤",IF(D23>=75%,"⬤",IF(D23>=60%,"⬤","⬤"))) -> #N/A | D23: =MIN(G23/H23,150%) -> #N/A | E23: 0.9 | F23: 0.1 | G23: =IFERROR(COUNTIF('Act Campo'!$Q$2:$Q$971,$H$4),0) -> 0 | H23: =VLOOKUP(H4,'Tabla dinam gestion comercial'!P:U,6,0) -> #N/A | I23: Mide el cumplimiento de actividades y parcelas realizadas por los promotores del territorio frente a la meta esperada. Por cada promotor se esperan 3 actividades trimestrales y 0,5 parcelas, con reconocimiento máximo hasta el 150%.
A24: #VALUE! | B24: Hectáreas de cultivos impactados | C24: =IF(D24>=90%,"⬤",IF(D24>=75%,"⬤",IF(D24>=60%,"⬤","⬤"))) -> ⬤ | D24: =IFERROR(MIN(G24/H24,150%),0) -> 0 | E24: 0.9 | F24: 0.05 | G24: =SUMIF(Fincas!$B:$B, $H$4, Fincas!$F:$F) -> 0 | H24: =ROUNDUP(SUMIFS('Tabla dinam gestion comercial'!$V:$V,'Tabla dinam gestion comercial'!$P:$P,$H$4,'Tabla dinam gestion comercial'!$Q:$Q,"*Promotor*")*3,0) -> 0 | I24: Mide las hectáreas gestionadas en el período frente a la meta del territorio. Cada promotor debe gestionar 30 hectáreas mensuales, equivalentes a 90 por trimestre, con reconocimiento de cumplimiento máximo hasta el 150%.
A25: #VALUE! | B25: Cultivos impactados | C25: =IF(D25>=90%,"⬤",IF(D25>=75%,"⬤",IF(D25>=60%,"⬤","⬤"))) -> ⬤ | D25: =IFERROR(MIN(G25/H25, 1.5), 0) -> 0 | E25: 0.9 | F25: 0.05 | G25: =COUNTIFS(Fincas!$B:$B, $H$4, Fincas!$D:$D, "<>") -> 0 | H25: =IFERROR(ROUNDUP(SUMIFS('Tabla dinam gestion comercial'!$W:$W,'Tabla dinam gestion comercial'!$P:$P,$H$4,'Tabla dinam gestion comercial'!$Q:$Q,"*PROMOTOR*"),0),0) -> 0 | I25: Mide los cultivos gestionados en el período frente a la meta del territorio. Cada promotor debe gestionar mínimo 1 cultivo mensual, equivalente a 3 por trimestre, con reconocimiento de cumplimiento máximo hasta el 150%.
A26: #VALUE! | B26: Gestión de Cultivos Impactados | C26: =IF(D26>=90%,"⬤",IF(D26>=75%,"⬤",IF(D26>=60%,"⬤","⬤"))) -> ⬤ | D26: =(D24+D25)/2 -> 0 | E26: 0.9 | F26: =F24+F25 -> 0.1
A27: #VALUE! | B27: "Enfócate en las oportunidades de mejora y mantén el ritmo en tus fortalezas." ¡Tú puedes alcanzar tus objetivos! | E27: Requiere mejora (<60%) | G27: En desarrollo (60% -74 %) | H27: Bueno (>=75% - 89%) | I27: Excelente (>=90%)
A30: Oportunidades | D30: Fortalezas | G30: Resumen ejecutivo | I30: Plan de acción sugerido
A31: =IF($L$8>=90,"El reto del territorio es sostener el nivel alcanzado y anticipar posibles desviaciones. Se recomienda revisar los indicadores cercanos al límite y mantener control sobre los frentes de mayor impacto.",IF($L$8>=75,"La principal oportunidad está en cerrar las brechas que impiden llegar al nivel excelente. Es clave ajustar la ejecución del territorio y priorizar los indicadores pendientes.",IF($L$8>=59,"El territorio debe concentrarse en los indicadores con menor cumplimiento. Reforzar la planificación, priorizar acciones de impacto y hacer seguimiento a los compromisos permitirá mejorar el resultado general.", "La prioridad del territorio es recuperar los indicadores críticos. Se requiere definir acciones concretas, responsables y seguimiento frecuente para mejorar el cumplimiento."))) -> #DIV/0! | D31: =IF($L$8>=90,"El territorio muestra fortalezas consolidadas en su ejecución comercial. Se destacan la consistencia en la gestión, el cumplimiento de indicadores clave y la capacidad para superar las metas del período.",IF($L$8>=75,"El territorio cuenta con una base de gestión favorable. Se evidencian avances relevantes en indicadores principales y una ejecución cercana al nivel esperado.",IF($L$8>=59,"Aunque persisten oportunidades de mejora, se identifican avances puntuales en algunos indicadores. Estos resultados pueden servir como base para fortalecer la gestión del territorio.", "Aunque el resultado general es bajo, algunos indicadores muestran señales positivas. Estos avances deben tomarse como punto de partida para orientar el plan de mejora del territorio."))) -> #DIV/0! | G31: =IF($L$8>=90,"El territorio presenta un desempeño sobresaliente frente a los objetivos definidos. La gestión refleja consistencia, disciplina comercial y buen cumplimiento de los indicadores clave. El reto es sostener este nivel en los próximos períodos.",IF($L$8>=75,"El territorio muestra un buen desempeño en el período evaluado. Se evidencian avances importantes frente a los objetivos, aunque aún es necesario reforzar los indicadores pendientes para alcanzar el nivel excelente.",IF($L$8>=59,"El territorio presenta avances parciales, pero aún existen oportunidades de mejora. Es clave enfocar la gestión en los indicadores de mayor impacto para fortalecer el resultado general.", "El territorio presenta brechas importantes frente a los objetivos definidos. Se requiere revisar la estrategia, priorizar los indicadores críticos y ejecutar un plan de mejora con seguimiento cercano."))) -> #DIV/0! | I31: =IF($H$7>=90,"Mantener el desempeño del territorio, controlar los indicadores cercanos al límite y documentar las buenas prácticas que pueden replicarse.",IF($H$7>=75,"Cerrar las brechas frente al nivel excelente. Definir acciones concretas, responsables y fechas de seguimiento por indicador.",IF($H$7>=59,"Reforzar el plan de trabajo del territorio, priorizando los indicadores con menor cumplimiento y fortaleciendo la planificación semanal.", "Activar un plan de mejora para los indicadores críticos del territorio. Definir prioridades, responsables y seguimiento semanal."))) -> Activar un plan de mejora para los indicadores críticos del territorio. Definir prioridades, responsables y seguimiento semanal.

Sheet Trimestre
A1: #VALUE! | D1: Reporte de desempeño comercial - Territorio
D2: Reporte De Desempeño Comercial | G2: Nombre | H2: Luisa Fernanda Quiceno Restrepo
D3: Resumen Trimestral | G3: Cargo: | H3: =VLOOKUP(H2,'Tabla dinam gestion comercial'!O:Q,3,0) -> #N/A
D4: Trimestre 1 | G4: Territorio | H4: =VLOOKUP(H2,'Tabla dinam gestion comercial'!O:P,2,0) -> #N/A
D5: Enero- Marzo de 2026 | G5: Empresa: | H5: =VLOOKUP(H2,'Tabla dinam gestion comercial'!O:R,4,0) -> #N/A
A6: Resultado Global
A7: =SUMPRODUCT($D$14:$D$24, $F$14:$F$24) -> #DIV/0!
J8: Valor | K8: =A7*100 -> #DIV/0! | L8: =ROUND(K8,0)&"%" -> #DIV/0!
J9: Restante | K9: =100-K8 -> #DIV/0!
J10: Oculto | K10: 100
A11: =IF(A7>=90%,"Excelente",IF(A7>=75%,"Destacado",IF(A7>=59%,"En desarrollo","Crítico"))) -> #DIV/0!
A12: INDICADORES CLAVE
A13: Indicador | D13: Cumplimiento | E13: Meta | F13: Peso | G13: Gestión real Prom X 3 meses | H13: Meta Esperada prom mes | I13: Criterios de medición
A14: #VALUE! | B14: Ejecución Visitas | C14: =IF(D14>=90%,"⬤",IF(D14>=75%,"⬤",IF(D14>=60%,"⬤","⬤"))) -> ⬤ | D14: =IFERROR(MIN(100%,G14/H14),0) -> 0 | E14: 0.9 | F14: 0.1 | G14: =IFERROR(SUMIFS('Tabla dinam gestion comercial'!$F:$F,'Tabla dinam gestion comercial'!$B:$B,$H$2)/3,0) -> 0 | H14: =MIN(2000,SUMIFS('Tabla dinam gestion comercial'!$M:$M,'Tabla dinam gestion comercial'!$B:$B,$H$2)/3) -> 0 | I14: Compara las visitas realizadas con la meta mensual. Cumplir o superar la meta equivale a 100%. El resultado es el promedio de los meses evaluados.
A15: #VALUE! | B15: Cobertura Clientes | C15: =IF(D15>=90%,"⬤",IF(D15>=75%,"⬤",IF(D15>=60%,"⬤","⬤"))) -> ⬤ | D15: =IFERROR(MIN(100%,G15/H15),0) -> 0 | E15: 0.9 | F15: 0.1 | G15: =IFERROR(SUMIFS('Tabla dinam gestion comercial'!$D:$D,'Tabla dinam gestion comercial'!$B:$B,$H$2)/3,0) -> 0 | H15: =IFERROR(SUMIFS('Tabla dinam gestion comercial'!$C$2:$C$62,'Tabla dinam gestion comercial'!$B$2:$B$62,$H$2)/3,0)/3 -> 0 | I15: Mide cuántos clientes del territorio fueron visitados frente a la meta mensual asignada. Se calcula con el promedio de clientes visitados durante los meses evaluados y se compara contra la meta de cobertura. La meta no se acumula entre meses.
A16: #VALUE! | B16: Nuevos Clientes | C16: =IF(D16>=90%,"⬤",IF(D16>=75%,"⬤",IF(D16>=60%,"⬤","⬤"))) -> #DIV/0! | D16: =G16/H16 -> #DIV/0! | E16: 0.9 | F16: 0.1 | G16: =SUMIFS('Tabla dinam gestion comercial'!$I:$I,'Tabla dinam gestion comercial'!$B:$B,$H$2)/3 -> 0 | H16: =ROUNDUP(SUMIFS('Tabla dinam gestion comercial'!$H:$H,'Tabla dinam gestion comercial'!$B:$B,$H$2)/12,0) -> 0 | I16: Cuenta los clientes recuperados y los clientes nuevos que registran una gestión o una venta. La meta mensual corresponde a la meta anual dividida entre 12 meses.
A17: Indicador | D17: Cumplimiento | E17: Meta | F17: Peso | G17: Gestión Real | H17: Meta acum. período | I17: Criterios de medición
A18: #VALUE! | B18: Recomendados | C18: =IF(D18>=90%,"⬤",IF(D18>=75%,"⬤",IF(D18>=60%,"⬤","⬤"))) -> ⬤ | D18: =IFERROR((G18/H18),"0") -> 0 | E18: 0.9 | F18: 0.2 | G18: =SUMIFS(Tecnico!$D:$D,Tecnico!$A:$A,$H$4) -> 0 | H18: =SUMIFS(Tecnico!$C:$C,Tecnico!$A:$A,$H$4) -> 0 | I18: Suma las recomendaciones generadas en enero, febrero y marzo, y compara ese total contra la meta acumulada del período. El resultado muestra qué porcentaje de la meta trimestral se alcanzó.
A19: #VALUE! | B19: Referencias | C19: =IF(D19>=90%,"⬤",IF(D19>=75%,"⬤",IF(D19>=60%,"⬤","⬤"))) -> ⬤ | D19: =IF(AND(G19=0, H19=0), 100%, IF(G19=0, 0%, G19/H19)) -> 1 | E19: 0.9 | F19: 0.1 | G19: =SUMIFS(Tecnico!$J:$J,Tecnico!$A:$A,$H$4) -> 0 | H19: =SUMIFS(Tecnico!$H:$H,Tecnico!$A:$A,$H$4)/3 -> 0 | I19: Mide cuántas referencias se gestionaron frente a la meta esperada. Se suman las referencias de enero, febrero y marzo, y se comparan contra la meta promedio del trimestre.
A20: #VALUE! | B20: leads Calificados | C20: =IF(D20>=90%,"⬤",IF(D20>=75%,"⬤",IF(D20>=60%,"⬤","⬤"))) -> ⬤ | D20: =IF(H20=0,0,IFERROR(G20/H20,0)) -> 0 | E20: 0.9 | F20: 0.1 | G20: =IFERROR(VLOOKUP(H2,Leads!C:H,2,0),"0") -> 0 | H20: =MAX(1,IFERROR(SUMIFS(Leads!$D:$D,Leads!$C:$C,$H$2,Leads!$I:$I,"Enero"),0))+MAX(1,IFERROR(SUMIFS(Leads!$D:$D,Leads!$C:$C,$H$2,Leads!$I:$I,"Febrero"),0))+MAX(1,IFERROR(SUMIFS(Leads!$D:$D,Leads!$C:$C,$H$2,Leads!$I:$I,"Marzo"),0)) -> 3 | I20: Mide cuántos de los leads creados en el período fueron gestionados. El resultado corresponde al porcentaje de atención sobre el total de leads generados.
A21: #VALUE! | B21: leads Calificados A Tiempo | C21: =IF(D21>=90%,"⬤",IF(D21>=75%,"⬤",IF(D21>=60%,"⬤","⬤"))) -> ⬤ | D21: =IF(H21=0,0,IFERROR(G21/H21,0)) -> 0 | E21: 0.9 | F21: 0.1 | G21: =IFERROR(VLOOKUP(H2,Leads!$K:$P,6,0),0) -> 0 | H21: =MAX(1,IFERROR(SUMIFS(Leads!$D:$D,Leads!$C:$C,$H$2,Leads!$I:$I,"Enero"),0))+MAX(1,IFERROR(SUMIFS(Leads!$D:$D,Leads!$C:$C,$H$2,Leads!$I:$I,"Febrero"),0))+MAX(1,IFERROR(SUMIFS(Leads!$D:$D,Leads!$C:$C,$H$2,Leads!$I:$I,"Marzo"),0)) -> 3 | I21: Mide el porcentaje de leads que fueron calificados dentro del tiempo establecido. Se compara la cantidad de leads calificados oportunamente frente al total de leads que debían ser gestionados en el período.
A22: #VALUE! | B22: Impacto en clientes (Actividades de Campo) | C22: =IF(D22>=90%,"⬤",IF(D22>=75%,"⬤",IF(D22>=60%,"⬤","⬤"))) -> #N/A | D22: =MIN(G22/H22,150%) -> #N/A | E22: 0.9 | F22: 0.1 | G22: =COUNTIFS('Act Campo'!$Q$2:$Q$997,$H$4,'Act Campo'!$AF$2:$AF$997,"Enero") +COUNTIFS('Act Campo'!$Q$2:$Q$997,$H$4,'Act Campo'!$AF$2:$AF$997,"Febrero") +COUNTIFS('Act Campo'!$Q$2:$Q$997,$H$4,'Act Campo'!$AF$2:$AF$997,"Marzo") -> 0 | H22: =VLOOKUP(H4,'Tabla dinam gestion comercial'!P:U,6,0) -> #N/A | I22: Mide el cumplimiento de actividades y parcelas frente a la meta del territorio. Por cada promotor se esperan 3 actividades trimestrales y 0,5 parcelas, con reconocimiento máximo hasta el 150%
A23: #VALUE! | B23: Hectareas Cultivos impactados | C23: =IF(D23>=90%,"⬤",IF(D23>=75%,"⬤",IF(D23>=60%,"⬤","⬤"))) -> #DIV/0! | D23: =MIN(G23/H23,150%) -> #DIV/0! | E23: 0.9 | F23: 0.05 | G23: =SUMIF(Fincas!$B:$B, $H$4, Fincas!$F:$F) -> 0 | H23: =ROUNDUP(_xlfn.MAXIFS('Tabla dinam gestion comercial'!$V:$V,'Tabla dinam gestion comercial'!$O:$O,$H$2)*3,0) -> 0 | I23: Mide las hectáreas gestionadas en el período frente a la meta del territorio. Cada promotor debe gestionar 30 hectáreas mensuales, equivalentes a 90 por trimestre, con reconocimiento de cumplimiento máximo hasta el 150%.
A24: #VALUE! | B24: Cultivos impactados | C24: =IF(D24>=90%,"⬤",IF(D24>=75%,"⬤",IF(D24>=60%,"⬤","⬤"))) -> ⬤ | D24: =IFERROR(MIN(G24/H24, 1.5), 0) -> 0 | E24: 0.9 | F24: 0.05 | G24: =COUNTIFS(Fincas!$B:$B, $H$4, Fincas!$D:$D, "<>") -> 0 | H24: =ROUNDUP(SUMIFS('Tabla dinam gestion comercial'!$W:$W,'Tabla dinam gestion comercial'!$O:$O,$H$2),0) -> 0 | I24: Mide los cultivos gestionados en el período frente a la meta del territorio. Cada promotor debe gestionar mínimo 1 cultivo mensual, equivalente a 3 por trimestre, con reconocimiento de cumplimiento máximo hasta el 150%.
A25: #VALUE! | B25: "Enfocate en las oportunidades de mejora y mantén el ritmo en tus fortalezas." ¡Tu puedes alcanzar tus objetivos! | E25: Requiere mejora (<60%) | G25: En Desarrollo (60% - 74 %) | H25: Bueno (>=75% - 89%) | I25: Excelente (>=90%)
A28: Oportunidades | D28: Fortalezas | G28: Resumen Ejecutivo | I28: Plan de acción sugerido
A29: =IF($L$8>=90,"El reto del territorio es sostener el nivel alcanzado y anticipar posibles desviaciones. Se recomienda revisar los indicadores cercanos al límite y mantener control sobre los frentes de mayor impacto.",IF($L$8>=75,"La principal oportunidad está en cerrar las brechas que impiden llegar al nivel excelente. Es clave ajustar la ejecución del territorio y priorizar los indicadores pendientes.",IF($L$8>=59,"El territorio debe concentrarse en los indicadores con menor cumplimiento. Reforzar la planificación, priorizar acciones de impacto y hacer seguimiento a los compromisos permitirá mejorar el resultado general.", "La prioridad del territorio es recuperar los indicadores críticos. Se requiere definir acciones concretas, responsables y seguimiento frecuente para mejorar el cumplimiento."))) -> #DIV/0! | D29: =IF($L$8>=90,"El territorio muestra fortalezas consolidadas en su ejecución comercial. Se destacan la consistencia en la gestión, el cumplimiento de indicadores clave y la capacidad para superar las metas del período.",IF($L$8>=75,"El territorio cuenta con una base de gestión favorable. Se evidencian avances relevantes en indicadores principales y una ejecución cercana al nivel esperado.",IF($L$8>=59,"Aunque persisten oportunidades de mejora, se identifican avances puntuales en algunos indicadores. Estos resultados pueden servir como base para fortalecer la gestión del territorio.", "Aunque el resultado general es bajo, algunos indicadores muestran señales positivas. Estos avances deben tomarse como punto de partida para orientar el plan de mejora del territorio."))) -> #DIV/0! | G29: =IF($L$8>=90,"El territorio presenta un desempeño sobresaliente frente a los objetivos definidos. La gestión refleja consistencia, disciplina comercial y buen cumplimiento de los indicadores clave. El reto es sostener este nivel en los próximos períodos.",IF($L$8>=75,"El territorio muestra un buen desempeño en el período evaluado. Se evidencian avances importantes frente a los objetivos, aunque aún es necesario reforzar los indicadores pendientes para alcanzar el nivel excelente.",IF($L$8>=59,"El territorio presenta avances parciales, pero aún existen oportunidades de mejora. Es clave enfocar la gestión en los indicadores de mayor impacto para fortalecer el resultado general.", "El territorio presenta brechas importantes frente a los objetivos definidos. Se requiere revisar la estrategia, priorizar los indicadores críticos y ejecutar un plan de mejora con seguimiento cercano."))) -> #DIV/0! | I29: =IF($H$7>=90,"Mantener el desempeño del territorio, controlar los indicadores cercanos al límite y documentar las buenas prácticas que pueden replicarse.",IF($H$7>=75,"Cerrar las brechas frente al nivel excelente. Definir acciones concretas, responsables y fechas de seguimiento por indicador.",IF($H$7>=59,"Reforzar el plan de trabajo del territorio, priorizando los indicadores con menor cumplimiento y fortaleciendo la planificación semanal.", "Activar un plan de mejora para los indicadores críticos del territorio. Definir prioridades, responsables y seguimiento semanal."))) -> Activar un plan de mejora para los indicadores críticos del territorio. Definir prioridades, responsables y seguimiento semanal.

Sheet Act Campo
A1: ID | B1: Estado | C1: Asunto | D1: ID de cliente | E1: Cliente | F1: Tipo de visita | G1: Propietario | H1: LinkUbicacion | I1: Dirección | J1: Estado1 | K1: Creado el | L1: Fecha/Hora de inicio | M1: Fecha/Hora de fin | N1: Fecha/Hora Inic.visita | O1: Fecha/Hora Fin visita | P1: Notas | Q1: Territorio de ventas | R1: Organización de ventas | S1: Creados por | T1: Ubicación | U1: Observaciones Visita | V1: Cultivo | W1: Recomendaciones | X1: Estado cultivo | Y1: Hectáreas | Z1: Oportunidades comerciales | AA1: Estado2 | AB1: zaUbicacion | AC1: Est.Fed./Prov. | AD1: Ciudad | AE1: Link Ubicacion | AF1: mes | AH1: Cuenta de ID de cliente
A2: 182138 | B2: Completado | C2: EVENTO INAUGURACIÓN NUEVA P.V | D2: 1571715 | E2: JARAMILLO ZAPATA NATALIA ANDREA MY PETS HUELLITAS CONSENTIDAS | F2: Evento Especial | G2: Elizabeth Sanmartin Vasquez | I2: CR 63 CL 57S 62 / 05088 BELLO / CO | J2: ANTIOQUIA | K2: 46053.405 | L2: 46053.354 | M2: 46053.583 | N2: 46053.405 | O2: 46053.583 | P2: EVENTO AGRIPAC | Q2: PYC NORTE 2 PECUARIA | R2: PEREZ Y CARDONA | S2: Elizabeth Sanmartin Vasquez | T2: JARAMILLO ZAPATA NATALIA ANDREA MY PETS HUELLITAS CONSENTIDAS / CR 63 CL 57S 62 / 05088 BELLO / CO | Y2: 0 | AB2: CR 63 CL 57S 62 / 05088 BELLO | AC2: ANTIOQUIA | AD2: BELLO | AF2: =TEXT(L2,"mmmm") -> enero | AH2: Territorio de ventas | AI2: mes | AJ2: Propietario | AK2: Tipo de visita | AL2: Total
A3: 182303 | B3: Completado | C3: Capacitacion sumitomo | D3: 1401434 | E3: AGRICOLA ANTIOQUIA GENERICO | F3: Visita Formación | G3: Edison Ferney Rivera Muñoz | I3: VRD LAS LAJAS / 05615 RIONEGRO / CO | J3: ANTIOQUIA | K3: 46053.603 | L3: 46042.333 | M3: 46042.708 | N3: 46053.603 | O3: 46053.603 | Q3: PYC AGRÍCOLA ANT ORIENTE B | R3: PEREZ Y CARDONA | S3: Edison Ferney Rivera Muñoz | T3: AGRICOLA ANTIOQUIA GENERICO / VRD LAS LAJAS / 05615 RIONEGRO / CO | Y3: 0 | AB3: VRD LAS LAJAS / 05615 RIONEGRO | AC3: ANTIOQUIA | AD3: RIONEGRO | AF3: =TEXT(L3,"mmmm") -> enero | AH3: PYC AGRÍCOLA ANT CÓRDOBA | AI3: febrero | AJ3: (Vacante) Jonathan De Jesús Salcedo Arango | AK3: Día de campo | AL3: 1
A4: 182304 | B4: Completado | C4: Capacitacion agafer | D4: 1401434 | E4: AGRICOLA ANTIOQUIA GENERICO | F4: Visita Formación | G4: Edison Ferney Rivera Muñoz | I4: VRD LAS LAJAS / 05615 RIONEGRO / CO | J4: ANTIOQUIA | K4: 46053.603 | L4: 46043.333 | M4: 46043.708 | N4: 46053.603 | O4: 46053.603 | Q4: PYC AGRÍCOLA ANT ORIENTE B | R4: PEREZ Y CARDONA | S4: Edison Ferney Rivera Muñoz | T4: AGRICOLA ANTIOQUIA GENERICO / VRD LAS LAJAS / 05615 RIONEGRO / CO | Y4: 0 | AB4: VRD LAS LAJAS / 05615 RIONEGRO | AC4: ANTIOQUIA | AD4: RIONEGRO | AF4: =TEXT(L4,"mmmm") -> enero | AH4: PYC AGRÍCOLA ANT CÓRDOBA | AI4: marzo | AJ4: (Vacante) Jonathan De Jesús Salcedo Arango | AK4: Día de campo | AL4: 14
A5: 179366 | B5: Completado | C5: Manejo C4C con alejandro | D5: 1401434 | E5: AGRICOLA ANTIOQUIA GENERICO | F5: Visita Formación | G5: Edison Ferney Rivera Muñoz | I5: VRD LAS LAJAS / 05615 RIONEGRO / CO | J5: ANTIOQUIA | K5: 46030.557 | L5: 46024.375 | M5: 46024.625 | N5: 46030.557 | O5: 46030.557 | Q5: PYC AGRÍCOLA ANT ORIENTE B | R5: PEREZ Y CARDONA | S5: Edison Ferney Rivera Muñoz | T5: AGRICOLA ANTIOQUIA GENERICO / VRD LAS LAJAS / 05615 RIONEGRO / CO | Y5: 0 | AB5: VRD LAS LAJAS / 05615 RIONEGRO | AC5: ANTIOQUIA | AD5: RIONEGRO | AF5: =TEXT(L5,"mmmm") -> enero | AH5: PYC AGRÍCOLA ANT CÓRDOBA | AI5: marzo | AJ5: Jairo Jesús Morales Doria | AK5: Evento Especial | AL5: 1
A6: 181466 | B6: Completado | C6: Capacitación a mostradores de comsab | D6: 1333635 | E6: COOPERATIVA AGROMULTIACTIVA SAN BARTOLO COMSAB | F6: Evento Especial | G6: (vacante) Alex García Moncada | I6: DG 53 53 47 / 05034 ANDES / CO | J6: ANTIOQUIA | K6: 46049.618 | L6: 46049.625 | M6: 46049.729 | N6: 46049.787 | O6: 46049.787 | P6: Nos acompaña Eduardo Sáenz sumitomo | Q6: PYC AGRÍCOLA ANT SUROESTE | R6: PEREZ Y CARDONA | S6: (vacante) Alex García Moncada | T6: COOPERATIVA AGROMULTIACTIVA SAN BARTOLO COMSAB / DG 53 53 47 / 05034 ANDES / CO | Y6: 0 | AB6: DG 53 53 47 / 05034 ANDES | AC6: ANTIOQUIA | AD6: ANDES | AF6: =TEXT(L6,"mmmm") -> enero | AH6: PYC AGRÍCOLA ANT NORTE | AI6: marzo | AJ6: Carolina María Escobar Londoño | AK6: Evento Especial | AL6: 1
A7: 183061 | B7: Completado | C7: Capacitación a Mostradores, con probelte | D7: 1333635 | E7: COOPERATIVA AGROMULTIACTIVA SAN BARTOLO COMSAB | F7: Evento Especial | G7: (vacante) Alex García Moncada | I7: DG 53 53 47 / 05034 ANDES / CO | J7: ANTIOQUIA | K7: 46059.37 | L7: 46056.604 | M7: 46056.708 | N7: 46059.37 | O7: 46059.37 | Q7: PYC AGRÍCOLA ANT SUROESTE | R7: PEREZ Y CARDONA | S7: (vacante) Alex García Moncada | T7: COOPERATIVA AGROMULTIACTIVA SAN BARTOLO COMSAB / DG 53 53 47 / 05034 ANDES / CO | Y7: 0 | AB7: DG 53 53 47 / 05034 ANDES | AC7: ANTIOQUIA | AD7: ANDES | AF7: =TEXT(L7,"mmmm") -> febrero | AH7: PYC AGRÍCOLA ANT NORTE | AI7: marzo | AJ7: Marcela Ramirez Ramirez | AK7: Evento Especial | AL7: 1
A8: 180096 | B8: Completado | C8: Reunion equipo suroeste y sumitomo | D8: 1000 | E8: PEREZ Y CARDONA | F8: Visita Formación | G8: Sara Ruíz Restrepo | I8: CO | K8: 46037.451 | L8: 46037.292 | M8: 46037.708 | N8: 46037.451 | O8: 46049.492 | Q8: PYC AGRÍCOLA ANT SUROESTE | R8: PEREZ Y CARDONA | S8: Sara Ruíz Restrepo | T8: PEREZ Y CARDONA / CO | Y8: 0 | AB8: CO | AF8: =TEXT(L8,"mmmm") -> enero | AH8: PYC AGRÍCOLA ANT ORIENTE A | AI8: enero | AJ8: Juan Esteban Montoya Serna | AK8: Evento Especial | AL8: 1
A9: 182539 | B9: Completado | C9: Capacitación probelte en comsab | D9: 1333635 | E9: COOPERATIVA AGROMULTIACTIVA SAN BARTOLO COMSAB | F9: Evento Especial | G9: Sara Ruíz Restrepo | I9: DG 53 53 47 / 05034 ANDES / CO | J9: ANTIOQUIA | K9: 46056.59 | L9: 46056.583 | M9: 46056.625 | N9: 46056.591 | O9: 46056.667 | P9: Se capacitación los mostradores y quedaron muy contentos con la información | Q9: PYC AGRÍCOLA ANT SUROESTE | R9: PEREZ Y CARDONA | S9: Sara Ruíz Restrepo | T9: COOPERATIVA AGROMULTIACTIVA SAN BARTOLO COMSAB / DG 53 53 47 / 05034 ANDES / CO | Y9: 0 | AB9: DG 53 53 47 / 05034 ANDES | AC9: ANTIOQUIA | AD9: ANDES | AF9: =TEXT(L9,"mmmm") -> febrero | AH9: PYC AGRÍCOLA ANT ORIENTE B | AI9: febrero | AJ9: Edison Ferney Rivera Muñoz | AK9: Evento Especial | AL9: 2
A10: 182197 | B10: Completado | C10: Congreso nacional de productores de papa | D10: 1460096 | E10: GRUPO EMPRESARIAL IMPULSAGRO SEDE VENTORRILLO | F10: Visita Formación | G10: Julio Andrés Cuspoca Martínez | I10: VEREDA HUERTA GRANDE SECTOR VENTORROLLO / 15104 BOYACA / CO | J10: BOYACA | K10: 46055.237 | L10: 46055.417 | M10: 46055.542 | N10: 46055.429 | O10: 46055.501 | Q10: GALAGRO BOYACA NAL. | R10: GALAGRO | S10: Julio Andrés Cuspoca Martínez | T10: GRUPO EMPRESARIAL IMPULSAGRO SEDE VENTORRILLO / VEREDA HUERTA GRANDE SECTOR VENTORROLLO / 15104 BOYA | Y10: 0 | AB10: VEREDA HUERTA GRANDE SECTOR VENTORROLLO / 15104 BOYA | AC10: BOYACA | AD10: BOYACA | AF10: =TEXT(L10,"mmmm") -> febrero | AH10: PYC AGRÍCOLA ANT ORIENTE B | AI10: marzo | AJ10: Alejandro Suárez García | AK10: Evento Especial | AL10: 1
A11: 183107 | B11: Completado | C11: Capacitación | D11: 1480607 | E11: CORDOBA RONALDO COOIMPROSAM | F11: Visita Formación | G11: Juan José Lagos Regalado | I11: 52678 SAMANIEGO / CO | J11: NARIÑO | K11: 46059.776 | L11: 46059.792 | M11: 46059.812 | N11: 46059.777 | O11: 46059.843 | Q11: GALAGRO NARIÑO NAL. | R11: GALAGRO | S11: Juan José Lagos Regalado | T11: CORDOBA RONALDO COOIMPROSAM / CO | Y11: 0 | AB11: CO | AC11: NARIÑO | AD11: SAMANIEGO | AF11: =TEXT(L11,"mmmm") -> febrero | AH11: PYC AGRÍCOLA ANT SUROESTE | AI11: enero | AJ11: (vacante) Alex García Moncada | AK11: Evento Especial | AL11: 1
A12: 180229 | B12: Completado | C12: Asamblea fedepapa | D12: 1337069 | E12: FED COLOMBIANA DE PRODUCTORES DE PAPA FEDEPAPA | F12: Evento Especial | G12: Juan Esteban Montoya Serna | I12: CL 11 8 31 / 05400 LA UNION / CO | J12: ANTIOQUIA | K12: 46040.408 | L12: 46040.375 | M12: 46040.583 | N12: 46040.408 | O12: 46040.584 | Q12: PYC AGRÍCOLA ANT ORIENTE A | R12: PEREZ Y CARDONA | S12: Juan Esteban Montoya Serna | T12: FED COLOMBIANA DE PRODUCTORES DE PAPA FEDEPAPA / CL 11 8 31 / 05400 LA UNION / CO | Y12: 0 | AB12: CL 11 8 31 / 05400 LA UNION | AC12: ANTIOQUIA | AD12: LA UNION | AF12: =TEXT(L12,"mmmm") -> enero | AH12: PYC AGRÍCOLA ANT SUROESTE | AI12: febrero | AJ12: (vacante) Alex García Moncada | AK12: Evento Especial | AL12: 1
A13: 182632 | B13: Completado | C13: Fortalecimiento de conceptos Camporigen | D13: 1400707 | E13: GALAGRO ANTIOQUIA GENERICO | F13: Día de campo | G13: John Álvaro Correa Castaño | I13: 05541 PEÑOL / CO | J13: ANTIOQUIA | K13: 46056.459 | L13: 46056.312 | M13: 46056.458 | N13: 46056.459 | O13: 46056.459 | Q13: GALAGRO SUROESTE ANT. | R13: GALAGRO | S13: John Álvaro Correa Castaño | T13: GALAGRO ANTIOQUIA GENERICO / CO | Y13: 0 | AB13: CO | AC13: ANTIOQUIA | AD13: PEÑOL | AF13: =TEXT(L13,"mmmm") -> febrero | AH13: PYC AGRÍCOLA ANT SUROESTE | AI13: febrero | AJ13: Fabian Rueda Rueda | AK13: Evento Especial | AL13: 1
A14: 180587 | B14: Completado | C14: Capacitación agricultura regenerativa P Y C | D14: 1400707 | E14: GALAGRO ANTIOQUIA GENERICO | F14: Visita Formación | G14: Juan David Rojas Rivera | I14: 05541 PEÑOL / CO | J14: ANTIOQUIA | K14: 46042.797 | L14: 46043.542 | M14: 46043.688 | N14: 46043.477 | O14: 46044.243 | Q14: GALAGRO ANTIOQUIA COORDINACIÓN | R14: GALAGRO | S14: Juan David Rojas Rivera | T14: GALAGRO ANTIOQUIA GENERICO / CO | Y14: 0 | AB14: CO | AC14: ANTIOQUIA | AD14: PEÑOL | AF14: =TEXT(L14,"mmmm") -> enero | AH14: PYC AGRÍCOLA ANT SUROESTE | AI14: febrero | AJ14: Sara Ruíz Restrepo | AK14: Evento Especial | AL14: 2
A15: 182266 | B15: Completado | C15: Gira técnica eje cafetero | D15: 1400070 | E15: GALAGRO NACIONAL GENERICO | F15: Evento Especial | G15: Juan David Rojas Rivera | I15: 41551 PITALITO / CO | J15: HUILA | K15: 46055.396 | L15: 46055.333 | M15: 46055.896 | N15: 46055.396 | O15: 46055.835 | Q15: GALAGRO NACIONAL COORDINACIÓN | R15: GALAGRO | S15: Juan David Rojas Rivera | T15: GALAGRO NACIONAL GENERICO / CO | Y15: 0 | AB15: CO | AC15: HUILA | AD15: PITALITO | AF15: =TEXT(L15,"mmmm") -> febrero | AH15: PYC AGRÍCOLA ANT SUROESTE | AI15: marzo | AJ15: (vacante) Alex García Moncada | AK15: Día de campo | AL15: 1
A16: 182625 | B16: Completado | C16: Gira técnica Café Armenia | D16: 1400070 | E16: GALAGRO NACIONAL GENERICO | F16: Evento Especial | G16: Juan David Rojas Rivera | I16: 41551 PITALITO / CO | J16: HUILA | K16: 46056.861 | L16: 46056.333 | M16: 46056.875 | N16: 46056.862 | O16: 46056.862 | Q16: GALAGRO NACIONAL COORDINACIÓN | R16: GALAGRO | S16: Juan David Rojas Rivera | T16: GALAGRO NACIONAL GENERICO / CO | Y16: 0 | AB16: CO | AC16: HUILA | AD16: PITALITO | AF16: =TEXT(L16,"mmmm") -> febrero | AH16: PYC AGRÍCOLA ANT SUROESTE | AI16: marzo | AJ16: (vacante) Alex García Moncada | AK16: Evento Especial | AL16: 3
